Workbook

Sheet LEIA-ME
A1: CONVISITA | Base de dados das visitas do COMSAÚDE Americana
A2: Versão em planilha do mesmo modelo de dados do sistema web (pasta convisita). Cada informação é registrada uma única vez e os resultados são calculados por fórmula.
A4: Abas de cadastro e lançamento (texto azul = dado digitado):
A5: Dimensoes: as quatro dimensões do instrumento, com peso (soma = 100%) e pontuação máxima por item.
A6: Itens: os 14 itens indicadores (I.1 a IV.2), com meta esperada e fonte de observação.
A7: Faixas: limites do farol (vermelho, amarelo, verde) usados na classificação.
A8: Unidades: cadastro único dos estabelecimentos, com tipo e periodicidade de visita em meses.
A9: Visitas: uma linha por visita (id, unidade, ciclo, data, situação).
A10: Avaliacoes: uma linha por item avaliado em cada visita (14 linhas por visita). Pontuação 0, 1 ou 2; NA = 1 quando o item não se aplica; pontuação vazia com NA = 0 significa item não avaliado.
A12: Abas calculadas (não digitar):
A13: Resultados: pontos, percentual por dimensão e nota final de cada visita. A nota final é a média ponderada das dimensões avaliadas; quando uma dimensão inteira não se aplica, seu peso é redistribuído entre as demais.
A14: Painel: última visita de cada unidade nos ciclos indicados nas células C3 e F3, variação entre ciclos, próxima visita prevista e situação da agenda.
... A20: 3. Resultados e Painel se atualizam automaticamente (Resultados está preparado para até 400 visitas).

Sheet Painel
A1: Painel de desempenho por unidade
A2: Última visita válida de cada unidade nos ciclos escolhidos (altere C3 e F3). Farol conforme aba Faixas.
B3: Ciclo base: | C3: 2023 | E3: Ciclo comparado: | F3: 2026 | J3: Data de referência: | K3: =TODAY() -> 46298
A5: Unidade | B5: Tipo | C5: Data (base) | D5: Nota (base) | E5: Data (comparado) | F5: Nota (comparado) | G5: Variação (p.p.) | H5: Última visita | I5: Próxima prevista | J5: Situação da agenda | K5: % Infra. Física | L5: % Infra. Humana | M5: % Plano Municipal | N5: % Percepção Usuário
A6: =Unidades!B2 -> UAD - Unidade de Atendimento Domiciliar | B6: =Unidades!C2 -> Atenção Domiciliar | C6: =IF(_xlfn.MAXIFS(Resultados!$C$2:$C$401,Resultados!$D$2:$D$401,$A6,Resultados!$B$2:$B$401,$C$3,Resultados!$U$2:$U$401,1)=0,"",_xlfn.MAXIFS(Resultados!$C$2:$C$401,Resultados!$D$2:$D$401,$A6,Resultados!$B$2:$B$401,$C$3,Resultados!$U$2:$U$401,1)) -> 45106 | D6: =IF(C6="","",SUMIFS(Resultados!$R$2:$R$401,Resultados!$D$2:$D$401,$A6,Resultados!$B$2:$B$401,$C$3,Resultados!$C$2:$C$401,C6,Resultados!$U$2:$U$401,1)) -> 0.82589286 | E6: =IF(_xlfn.MAXIFS(Resultados!$C$2:$C$401,Resultados!$D$2:$D$401,$A6,Resultados!$B$2:$B$401,$F$3,Resultados!$U$2:$U$401,1)=0,"",_xlfn.MAXIFS(Resultados!$C$2:$C$401,Resultados!$D$2:$D$401,$A6,Resultados!$B$2:$B$401,$F$3,Resultados!$U$2:$U$401,1)) -> 46164 | F6: =IF(E6="","",SUMIFS(Resultados!$R$2:$R$401,Resultados!$D$2:$D$401,$A6,Resultados!$B$2:$B$401,$F$3,Resultados!$C$2:$C$401,E6,Resultados!$U$2:$U$401,1)) -> 1 | G6: =IF(OR(D6="",F6=""),"",(F6-D6)*100) -> 17.410714 | H6: =IF(_xlfn.MAXIFS(Resultados!$C$2:$C$401,Resultados!$D$2:$D$401,$A6,Resultados!$U$2:$U$401,1)=0,"",_xlfn.MAXIFS(Resultados!$C$2:$C$401,Resultados!$D$2:$D$401,$A6,Resultados!$U$2:$U$401,1)) -> 46164 | I6: =IF(H6="","",EDATE(H6,Unidades!F2)) -> 46348 | J6: =IF(Unidades!E2<>"ativa","suspensa",IF(H6="","sem visita",IF(I6<$K$3,"atrasada",IF(I6<=$K$3+30,"próximos 30 dias","em dia")))) -> em dia | K6: =IF(E6="","",SUMIFS(Resultados!$N$2:$N$401,Resultados!$D$2:$D$401,$A6,Resultados!$B$2:$B$401,$F$3,Resultados!$C$2:$C$401,E6,Resultados!$U$2:$U$401,1)) -> 1 | L6: =IF(E6="","",SUMIFS(Resultados!$O$2:$O$401,Resultados!$D$2:$D$401,$A6,Resultados!$B$2:$B$401,$F$3,Resultados!$C$2:$C$401,E6,Resultados!$U$2:$U$401,1)) -> 1 | M6: =IF(E6="","",SUMIFS(Resultados!$P$2:$P$401,Resultados!$D$2:$D$401,$A6,Resultados!$B$2:$B$401,$F$3,Resultados!$C$2:$C$401,E6,Resultados!$U$2:$U$401,1)) -> 1 | N6: =IF(E6="","",SUMIFS(Resultados!$Q$2:$Q$401,Resultados!$D$2:$D$401,$A6,Resultados!$B$2:$B$401,$F$3,Resultados!$C$2:$C$401,E6,Resultados!$U$2:$U$401,1)) -> 0
A7: =Unidades!B3 -> UBS Jardim São Paulo | B7: =Unidades!C3 -> Unidade Básica de Saúde (UBS) | C7: =IF(_xlfn.MAXIFS(Resultados!$C$2:$C$401,Resultados!$D$2:$D$401,$A7,Resultados!$B$2:$B$401,$C$3,Resultados!$U$2:$U$401,1)=0,"",_xlfn.MAXIFS(Resultados!$C$2:$C$401,Resultados!$D$2:$D$401,$A7,Resultados!$B$2:$B$401,$C$3,Resultados!$U$2:$U$401,1)) -> 45231 | D7: =IF(C7="","",SUMIFS(Resultados!$R$2:$R$401,Resultados!$D$2:$D$401,$A7,Resultados!$B$2:$B$401,$C$3,Resultados!$C$2:$C$401,C7,Resultados!$U$2:$U$401,1)) -> 0.85714286 | E7: =IF(_xlfn.MAXIFS(Resultados!$C$2:$C$401,Resultados!$D$2:$D$401,$A7,Resultados!$B$2:$B$401,$F$3,Resultados!$U$2:$U$401,1)=0,"",_xlfn.MAXIFS(Resultados!$C$2:$C$401,Resultados!$D$2:$D$401,$A7,Resultados!$B$2:$B$401,$F$3,Resultados!$U$2:$U$401,1)) -> 46090 | F7: =IF(E7="","",SUMIFS(Resultados!$R$2:$R$401,Resultados!$D$2:$D$401,$A7,Resultados!$B$2:$B$401,$F$3,Resultados!$C$2:$C$401,E7,Resultados!$U$2:$U$401,1)) -> 0.88392857 | G7: =IF(OR(D7="",F7=""),"",(F7-D7)*100) -> 2.6785714 | H7: =IF(_xlfn.MAXIFS(Resultados!$C$2:$C$401,Resultados!$D$2:$D$401,$A7,Resultados!$U$2:$U$401,1)=0,"",_xlfn.MAXIFS(Resultados!$C$2:$C$401,Resultados!$D$2:$D$401,$A7,Resultados!$U$2:$U$401,1)) -> 46090 | I7: =IF(H7="","",EDATE(H7,Unidades!F3)) -> 46274 | J7: =IF(Unidades!E3<>"ativa","suspensa",IF(H7="","sem visita",IF(I7<$K$3,"atrasada",IF(I7<=$K$3+30,"próximos 30 dias","em dia")))) -> atrasada | K7: =IF(E7="","",SUMIFS(Resultados!$N$2:$N$401,Resultados!$D$2:$D$401,$A7,Resultados!$B$2:$B$401,$F$3,Resultados!$C$2:$C$401,E7,Resultados!$U$2:$U$401,1)) -> 0.78571429 | L7: =IF(E7="","",SUMIFS(Resultados!$O$2:$O$401,Resultados!$D$2:$D$401,$A7,Resultados!$B$2:$B$401,$F$3,Resultados!$C$2:$C$401,E7,Resultados!$U$2:$U$401,1)) -> 1 | M7: =IF(E7="","",SUMIFS(Resultados!$P$2:$P$401,Resultados!$D$2:$D$401,$A7,Resultados!$B$2:$B$401,$F$3,Resultados!$C$2:$C$401,E7,Resultados!$U$2:$U$401,1)) -> 1 | N7: =IF(E7="","",SUMIFS(Resultados!$Q$2:$Q$401,Resultados!$D$2:$D$401,$A7,Resultados!$B$2:$B$401,$F$3,Resultados!$C$2:$C$401,E7,Resultados!$U$2:$U$401,1)) -> 0.75
A8: =Unidades!B4 -> Hospital Municipal Dr. Waldemar Tebaldi | B8: =Unidades!C4 -> Hospital | C8: =IF(_xlfn.MAXIFS(Resultados!$C$2:$C$401,Resultados!$D$2:$D$401,$A8,Resultados!$B$2:$B$401,$C$3,Resultados!$U$2:$U$401,1)=0,"",_xlfn.MAXIFS(Resultados!$C$2:$C$401,Resultados!$D$2:$D$401,$A8,Resultados!$B$2:$B$401,$C$3,Resultados!$U$2:$U$401,1)) | D8: =IF(C8="","",SUMIFS(Resultados!$R$2:$R$401,Resultados!$D$2:$D$401,$A8,Resultados!$B$2:$B$401,$C$3,Resultados!$C$2:$C$401,C8,Resultados!$U$2:$U$401,1)) | E8: =IF(_xlfn.MAXIFS(Resultados!$C$2:$C$401,Resultados!$D$2:$D$401,$A8,Resultados!$B$2:$B$401,$F$3,Resultados!$U$2:$U$401,1)=0,"",_xlfn.MAXIFS(Resultados!$C$2:$C$401,Resultados!$D$2:$D$401,$A8,Resultados!$B$2:$B$401,$F$3,Resultados!$U$2:$U$401,1)) -> 46091 | F8: =IF(E8="","",SUMIFS(Resultados!$R$2:$R$401,Resultados!$D$2:$D$401,$A8,Resultados!$B$2:$B$401,$F$3,Resultados!$C$2:$C$401,E8,Resultados!$U$2:$U$401,1)) -> 0.66517857 | G8: =IF(OR(D8="",F8=""),"",(F8-D8)*100) | H8: =IF(_xlfn.MAXIFS(Resultados!$C$2:$C$401,Resultados!$D$2:$D$401,$A8,Resultados!$U$2:$U$401,1)=0,"",_xlfn.MAXIFS(Resultados!$C$2:$C$401,Resultados!$D$2:$D$401,$A8,Resultados!$U$2:$U$401,1)) -> 46091 | I8: =IF(H8="","",EDATE(H8,Unidades!F4)) -> 46275 | J8: =IF(Unidades!E4<>"ativa","suspensa",IF(H8="","sem visita",IF(I8<$K$3,"atrasada",IF(I8<=$K$3+30,"próximos 30 dias","em dia")))) -> atrasada | K8: =IF(E8="","",SUMIFS(Resultados!$N$2:$N$401,Resultados!$D$2:$D$401,$A8,Resultados!$B$2:$B$401,$F$3,Resultados!$C$2:$C$401,E8,Resultados!$U$2:$U$401,1)) -> 0.78571429 | L8: =IF(E8="","",SUMIFS(Resultados!$O$2:$O$401,Resultados!$D$2:$D$401,$A8,Resultados!$B$2:$B$401,$F$3,Resultados!$C$2:$C$401,E8,Resultados!$U$2:$U$401,1)) -> 0.875 | M8: =IF(E8="","",SUMIFS(Resultados!$P$2:$P$401,Resultados!$D$2:$D$401,$A8,Resultados!$B$2:$B$401,$F$3,Resultados!$C$2:$C$401,E8,Resultados!$U$2:$U$401,1)) -> 0.5 | N8: =IF(E8="","",SUMIFS(Resultados!$Q$2:$Q$401,Resultados!$D$2:$D$401,$A8,Resultados!$B$2:$B$401,$F$3,Resultados!$C$2:$C$401,E8,Resultados!$U$2:$U$401,1)) -> 0.5
A9: =Unidades!B5 -> UPA Dona Rosa | B9: =Unidades!C5 -> Urgência e Emergência | C9: =IF(_xlfn.MAXIFS(Resultados!$C$2:$C$401,Resultados!$D$2:$D$401,$A9,Resultados!$B$2:$B$401,$C$3,Resultados!$U$2:$U$401,1)=0,"",_xlfn.MAXIFS(Resultados!$C$2:$C$401,Resultados!$D$2:$D$401,$A9,Resultados!$B$2:$B$401,$C$3,Resultados!$U$2:$U$401,1)) | D9: =IF(C9="","",SUMIFS(Resultados!$R$2:$R$401,Resultados!$D$2:$D$401,$A9,Resultados!$B$2:$B$401,$C$3,Resultados!$C$2:$C$401,C9,Resultados!$U$2:$U$401,1)) | E9: =IF(_xlfn.MAXIFS(Resultados!$C$2:$C$401,Resultados!$D$2:$D$401,$A9,Resultados!$B$2:$B$401,$F$3,Resultados!$U$2:$U$401,1)=0,"",_xlfn.MAXIFS(Resultados!$C$2:$C$401,Resultados!$D$2:$D$401,$A9,Resultados!$B$2:$B$401,$F$3,Resultados!$U$2:$U$401,1)) -> 46093 | F9: =IF(E9="","",SUMIFS(Resultados!$R$2:$R$401,Resultados!$D$2:$D$401,$A9,Resultados!$B$2:$B$401,$F$3,Resultados!$C$2:$C$401,E9,Resultados!$U$2:$U$401,1)) -> 0.96428571 | G9: =IF(OR(D9="",F9=""),"",(F9-D9)*100) | H9: =IF(_xlfn.MAXIFS(Resultados!$C$2:$C$401,Resultados!$D$2:$D$401,$A9,Resultados!$U$2:$U$401,1)=0,"",_xlfn.MAXIFS(Resultados!$C$2:$C$401,Resultados!$D$2:$D$401,$A9,Resultados!$U$2:$U$401,1)) -> 46093 | I9: =IF(H9="","",EDATE(H9,Unidades!F5)) -> 46277 | J9: =IF(Unidades!E5<>"ativa","suspensa",IF(H9="","sem visita",IF(I9<$K$3,"atrasada",IF(I9<=$K$3+30,"próximos 30 dias","em dia")))) -> atrasada | K9: =IF(E9="","",SUMIFS(Resultados!$N$2:$N$401,Resultados!$D$2:$D$401,$A9,Resultados!$B$2:$B$401,$F$3,Resultados!$C$2:$C$401,E9,Resultados!$U$2:$U$401,1)) -> 0.85714286 | L9: =IF(E9="","",SUMIFS(Resultados!$O$2:$O$401,Resultados!$D$2:$D$401,$A9,Resultados!$B$2:$B$401,$F$3,Resultados!$C$2:$C$401,E9,Resultados!$U$2:$U$401,1)) -> 1 | M9: =IF(E9="","",SUMIFS(Resultados!$P$2:$P$401,Resultados!$D$2:$D$401,$A9,Resultados!$B$2:$B$401,$F$3,Resultados!$C$2:$C$401,E9,Resultados!$U$2:$U$401,1)) -> 1 | N9: =IF(E9="","",SUMIFS(Resultados!$Q$2:$Q$401,Resultados!$D$2:$D$401,$A9,Resultados!$B$2:$B$401,$F$3,Resultados!$C$2:$C$401,E9,Resultados!$U$2:$U$401,1)) -> 1
A10: =Unidades!B6 -> Banco de Sangue | B10: =Unidades!C6 -> Apoio Diagnóstico e Terapêutico | C10: =IF(_xlfn.MAXIFS(Resultados!$C$2:$C$401,Resultados!$D$2:$D$401,$A10,Resultados!$B$2:$B$401,$C$3,Resultados!$U$2:$U$401,1)=0,"",_xlfn.MAXIFS(Resultados!$C$2:$C$401,Resultados!$D$2:$D$401,$A10,Resultados!$B$2:$B$401,$C$3,Resultados!$U$2:$U$401,1)) | D10: =IF(C10="","",SUMIFS(Resultados!$R$2:$R$401,Resultados!$D$2:$D$401,$A10,Resultados!$B$2:$B$401,$C$3,Resultados!$C$2:$C$401,C10,Resultados!$U$2:$U$401,1)) | E10: =IF(_xlfn.MAXIFS(Resultados!$C$2:$C$401,Resultados!$D$2:$D$401,$A10,Resultados!$B$2:$B$401,$F$3,Resultados!$U$2:$U$401,1)=0,"",_xlfn.MAXIFS(Resultados!$C$2:$C$401,Resultados!$D$2:$D$401,$A10,Resultados!$B$2:$B$401,$F$3,Resultados!$U$2:$U$401,1)) -> 46122 | F10: =IF(E10="","",SUMIFS(Resultados!$R$2:$R$401,Resultados!$D$2:$D$401,$A10,Resultados!$B$2:$B$401,$F$3,Resultados!$C$2:$C$401,E10,Resultados!$U$2:$U$401,1)) -> 0.625 | G10: =IF(OR(D10="",F10=""),"",(F10-D10)*100) | H10: =IF(_xlfn.MAXIFS(Resultados!$C$2:$C$401,Resultados!$D$2:$D$401,$A10,Resultados!$U$2:$U$401,1)=0,"",_xlfn.MAXIFS(Resultados!$C$2:$C$401,Resultados!$D$2:$D$401,$A10,Resultados!$U$2:$U$401,1)) -> 46122 | I10: =IF(H10="","",EDATE(H10,Unidades!F6)) -> 46305 | J10: =IF(Unidades!E6<>"ativa","suspensa",IF(H10="","sem visita",IF(I10<$K$3,"atrasada",IF(I10<=$K$3+30,"próximos 30 dias","em dia")))) -> próximos 30 dias | K10: =IF(E10="","",SUMIFS(Resultados!$N$2:$N$401,Resultados!$D$2:$D$401,$A10,Resultados!$B$2:$B$401,$F$3,Resultados!$C$2:$C$401,E10,Resultados!$U$2:$U$401,1)) -> 0.5 | L10: =IF(E10="","",SUMIFS(Resultados!$O$2:$O$401,Resultados!$D$2:$D$401,$A10,Resultados!$B$2:$B$401,$F$3,Resultados!$C$2:$C$401,E10,Resultados!$U$2:$U$401,1)) -> 1 | M10: =IF(E10="","",SUMIFS(Resultados!$P$2:$P$401,Resultados!$D$2:$D$401,$A10,Resultados!$B$2:$B$401,$F$3,Resultados!$C$2:$C$401,E10,Resultados!$U$2:$U$401,1)) -> 0.5 | N10: =IF(E10="","",SUMIFS(Resultados!$Q$2:$Q$401,Resultados!$D$2:$D$401,$A10,Resultados!$B$2:$B$401,$F$3,Resultados!$C$2:$C$401,E10,Resultados!$U$2:$U$401,1)) -> 0.5
A11: =Unidades!B7 -> UBS Parque Gramado | B11: =Unidades!C7 -> Unidade Básica de Saúde (UBS) | C11: =IF(_xlfn.MAXIFS(Resultados!$C$2:$C$401,Resultados!$D$2:$D$401,$A11,Resultados!$B$2:$B$401,$C$3,Resultados!$U$2:$U$401,1)=0,"",_xlfn.MAXIFS(Resultados!$C$2:$C$401,Resultados!$D$2:$D$401,$A11,Resultados!$B$2:$B$401,$C$3,Resultados!$U$2:$U$401,1)) | D11: =IF(C11="","",SUMIFS(Resultados!$R$2:$R$401,Resultados!$D$2:$D$401,$A11,Resultados!$B$2:$B$401,$C$3,Resultados!$C$2:$C$401,C11,Resultados!$U$2:$U$401,1)) | E11: =IF(_xlfn.MAXIFS(Resultados!$C$2:$C$401,Resultados!$D$2:$D$401,$A11,Resultados!$B$2:$B$401,$F$3,Resultados!$U$2:$U$401,1)=0,"",_xlfn.MAXIFS(Resultados!$C$2:$C$401,Resultados!$D$2:$D$401,$A11,Resultados!$B$2:$B$401,$F$3,Resultados!$U$2:$U$401,1)) -> 46156 | F11: =IF(E11="","",SUMIFS(Resultados!$R$2:$R$401,Resultados!$D$2:$D$401,$A11,Resultados!$B$2:$B$401,$F$3,Resultados!$C$2:$C$401,E11,Resultados!$U$2:$U$401,1)) -> 0.6875 | G11: =IF(OR(D11="",F11=""),"",(F11-D11)*100) | H11: =IF(_xlfn.MAXIFS(Resultados!$C$2:$C$401,Resultados!$D$2:$D$401,$A11,Resultados!$U$2:$U$401,1)=0,"",_xlfn.MAXIFS(Resultados!$C$2:$C$401,Resultados!$D$2:$D$401,$A11,Resultados!$U$2:$U$401,1)) -> 46156 | I11: =IF(H11="","",EDATE(H11,Unidades!F7)) -> 46340 | J11: =IF(Unidades!E7<>"ativa","suspensa",IF(H11="","sem visita",IF(I11<$K$3,"atrasada",IF(I11<=$K$3+30,"próximos 30 dias","em dia")))) -> em dia | K11: =IF(E11="","",SUMIFS(Resultados!$N$2:$N$401,Resultados!$D$2:$D$401,$A11,Resultados!$B$2:$B$401,$F$3,Resultados!$C$2:$C$401,E11,Resultados!$U$2:$U$401,1)) -> 0.5 | L11: =IF(E11="","",SUMIFS(Resultados!$O$2:$O$401,Resultados!$D$2:$D$401,$A11,Resultados!$B$2:$B$401,$F$3,Resultados!$C$2:$C$401,E11,Resultados!$U$2:$U$401,1)) -> 0.75 | M11: =IF(E11="","",SUMIFS(Resultados!$P$2:$P$401,Resultados!$D$2:$D$401,$A11,Resultados!$B$2:$B$401,$F$3,Resultados!$C$2:$C$401,E11,Resultados!$U$2:$U$401,1)) -> 0.5 | N11: =IF(E11="","",SUMIFS(Resultados!$Q$2:$Q$401,Resultados!$D$2:$D$401,$A11,Resultados!$B$2:$B$401,$F$3,Resultados!$C$2:$C$401,E11,Resultados!$U$2:$U$401,1)) -> 1
A12: =Unidades!B8 -> ESF São José | B12: =Unidades!C8 -> Estratégia Saúde da Família (ESF) | C12: =IF(_xlfn.MAXIFS(Resultados!$C$2:$C$401,Resultados!$D$2:$D$401,$A12,Resultados!$B$2:$B$401,$C$3,Resultados!$U$2:$U$401,1)=0,"",_xlfn.MAXIFS(Resultados!$C$2:$C$401,Resultados!$D$2:$D$401,$A12,Resultados!$B$2:$B$401,$C$3,Resultados!$U$2:$U$401,1)) -> 45254 | D12: =IF(C12="","",SUMIFS(Resultados!$R$2:$R$401,Resultados!$D$2:$D$401,$A12,Resultados!$B$2:$B$401,$C$3,Resultados!$C$2:$C$401,C12,Resultados!$U$2:$U$401,1)) -> 1 | E12: =IF(_xlfn.MAXIFS(Resultados!$C$2:$C$401,Resultados!$D$2:$D$401,$A12,Resultados!$B$2:$B$401,$F$3,Resultados!$U$2:$U$401,1)=0,"",_xlfn.MAXIFS(Resultados!$C$2:$C$401,Resultados!$D$2:$D$401,$A12,Resultados!$B$2:$B$401,$F$3,Resultados!$U$2:$U$401,1)) -> 46142 | F12: =IF(E12="","",SUMIFS(Resultados!$R$2:$R$401,Resultados!$D$2:$D$401,$A12,Resultados!$B$2:$B$401,$F$3,Resultados!$C$2:$C$401,E12,Resultados!$U$2:$U$401,1)) -> 0.78571429 | G12: =IF(OR(D12="",F12=""),"",(F12-D12)*100) -> -21.428571 | H12: =IF(_xlfn.MAXIFS(Resultados!$C$2:$C$401,Resultados!$D$2:$D$401,$A12,Resultados!$U$2:$U$401,1)=0,"",_xlfn.MAXIFS(Resultados!$C$2:$C$401,Resultados!$D$2:$D$401,$A12,Resultados!$U$2:$U$401,1)) -> 46142 | I12: =IF(H12="","",EDATE(H12,Unidades!F8)) -> 46325 | J12: =IF(Unidades!E8<>"ativa","suspensa",IF(H12="","sem visita",IF(I12<$K$3,"atrasada",IF(I12<=$K$3+30,"próximos 30 dias","em dia")))) -> próximos 30 dias | K12: =IF(E12="","",SUMIFS(Resultados!$N$2:$N$401,Resultados!$D$2:$D$401,$A12,Resultados!$B$2:$B$401,$F$3,Resultados!$C$2:$C$401,E12,Resultados!$U$2:$U$401,1)) -> 0.64285714 | L12: =IF(E12="","",SUMIFS(Resultados!$O$2:$O$401,Resultados!$D$2:$D$401,$A12,Resultados!$B$2:$B$401,$F$3,Resultados!$C$2:$C$401,E12,Resultados!$U$2:$U$401,1)) -> 1 | M12: =IF(E12="","",SUMIFS(Resultados!$P$2:$P$401,Resultados!$D$2:$D$401,$A12,Resultados!$B$2:$B$401,$F$3,Resultados!$C$2:$C$401,E12,Resultados!$U$2:$U$401,1)) -> 1 | N12: =IF(E12="","",SUMIFS(Resultados!$Q$2:$Q$401,Resultados!$D$2:$D$401,$A12,Resultados!$B$2:$B$401,$F$3,Resultados!$C$2:$C$401,E12,Resultados!$U$2:$U$401,1)) -> 0.5
A13: =Unidades!B9 -> ESF Praia Azul | B13: =Unidades!C9 -> Estratégia Saúde da Família (ESF) | C13: =IF(_xlfn.MAXIFS(Resultados!$C$2:$C$401,Resultados!$D$2:$D$401,$A13,Resultados!$B$2:$B$401,$C$3,Resultados!$U$2:$U$401,1)=0,"",_xlfn.MAXIFS(Resultados!$C$2:$C$401,Resultados!$D$2:$D$401,$A13,Resultados!$B$2:$B$401,$C$3,Resultados!$U$2:$U$401,1)) | D13: =IF(C13="","",SUMIFS(Resultados!$R$2:$R$401,Resultados!$D$2:$D$401,$A13,Resultados!$B$2:$B$401,$C$3,Resultados!$C$2:$C$401,C13,Resultados!$U$2:$U$401,1)) | E13: =IF(_xlfn.MAXIFS(Resultados!$C$2:$C$401,Resultados!$D$2:$D$401,$A13,Resultados!$B$2:$B$401,$F$3,Resultados!$U$2:$U$401,1)=0,"",_xlfn.MAXIFS(Resultados!$C$2:$C$401,Resultados!$D$2:$D$401,$A13,Resultados!$B$2:$B$401,$F$3,Resultados!$U$2:$U$401,1)) -> 46190 | F13: =IF(E13="","",SUMIFS(Resultados!$R$2:$R$401,Resultados!$D$2:$D$401,$A13,Resultados!$B$2:$B$401,$F$3,Resultados!$C$2:$C$401,E13,Resultados!$U$2:$U$401,1)) -> 0.90178571 | G13: =IF(OR(D13="",F13=""),"",(F13-D13)*100) | H13: =IF(_xlfn.MAXIFS(Resultados!$C$2:$C$401,Resultados!$D$2:$D$401,$A13,Resultados!$U$2:$U$401,1)=0,"",_xlfn.MAXIFS(Resultados!$C$2:$C$401,Resultados!$D$2:$D$401,$A13,Resultados!$U$2:$U$401,1)) -> 46190 | I13: =IF(H13="","",EDATE(H13,Unidades!F9)) -> 46373 | J13: =IF(Unidades!E9<>"ativa","suspensa",IF(H13="","sem visita",IF(I13<$K$3,"atrasada",IF(I13<=$K$3+30,"próximos 30 dias","em dia")))) -> em dia | K13: =IF(E13="","",SUMIFS(Resultados!$N$2:$N$401,Resultados!$D$2:$D$401,$A13,Resultados!$B$2:$B$401,$F$3,Resultados!$C$2:$C$401,E13,Resultados!$U$2:$U$401,1)) -> 0.85714286 | L13: =IF(E13="","",SUMIFS(Resultados!$O$2:$O$401,Resultados!$D$2:$D$401,$A13,Resultados!$B$2:$B$401,$F$3,Resultados!$C$2:$C$401,E13,Resultados!$U$2:$U$401,1)) -> 1 | M13: =IF(E13="","",SUMIFS(Resultados!$P$2:$P$401,Resultados!$D$2:$D$401,$A13,Resultados!$B$2:$B$401,$F$3,Resultados!$C$2:$C$401,E13,Resultados!$U$2:$U$401,1)) -> 1 | N13: =IF(E13="","",SUMIFS(Resultados!$Q$2:$Q$401,Resultados!$D$2:$D$401,$A13,Resultados!$B$2:$B$401,$F$3,Resultados!$C$2:$C$401,E13,Resultados!$U$2:$U$401,1)) -> 0.75
A14: =Unidades!B10 -> ESF Jardim Brasil | B14: =Unidades!C10 -> Estratégia Saúde da Família (ESF) | C14: =IF(_xlfn.MAXIFS(Resultados!$C$2:$C$401,Resultados!$D$2:$D$401,$A14,Resultados!$B$2:$B$401,$C$3,Resultados!$U$2:$U$401,1)=0,"",_xlfn.MAXIFS(Resultados!$C$2:$C$401,Resultados!$D$2:$D$401,$A14,Resultados!$B$2:$B$401,$C$3,Resultados!$U$2:$U$401,1)) | D14: =IF(C14="","",SUMIFS(Resultados!$R$2:$R$401,Resultados!$D$2:$D$401,$A14,Resultados!$B$2:$B$401,$C$3,Resultados!$C$2:$C$401,C14,Resultados!$U$2:$U$401,1)) | E14: =IF(_xlfn.MAXIFS(Resultados!$C$2:$C$401,Resultados!$D$2:$D$401,$A14,Resultados!$B$2:$B$401,$F$3,Resultados!$U$2:$U$401,1)=0,"",_xlfn.MAXIFS(Resultados!$C$2:$C$401,Resultados!$D$2:$D$401,$A14,Resultados!$B$2:$B$401,$F$3,Resultados!$U$2:$U$401,1)) -> 46162 | F14: =IF(E14="","",SUMIFS(Resultados!$R$2:$R$401,Resultados!$D$2:$D$401,$A14,Resultados!$B$2:$B$401,$F$3,Resultados!$C$2:$C$401,E14,Resultados!$U$2:$U$401,1)) -> 1 | G14: =IF(OR(D14="",F14=""),"",(F14-D14)*100) | H14: =IF(_xlfn.MAXIFS(Resultados!$C$2:$C$401,Resultados!$D$2:$D$401,$A14,Resultados!$U$2:$U$401,1)=0,"",_xlfn.MAXIFS(Resultados!$C$2:$C$401,Resultados!$D$2:$D$401,$A14,Resultados!$U$2:$U$401,1)) -> 46162 | I14: =IF(H14="","",EDATE(H14,Unidades!F10)) -> 46346 | J14: =IF(Unidades!E10<>"ativa","suspensa",IF(H14="","sem visita",IF(I14<$K$3,"atrasada",IF(I14<=$K$3+30,"próximos 30 dias","em dia")))) -> em dia | K14: =IF(E14="","",SUMIFS(Resultados!$N$2:$N$401,Resultados!$D$2:$D$401,$A14,Resultados!$B$2:$B$401,$F$3,Resultados!$C$2:$C$401,E14,Resultados!$U$2:$U$401,1)) -> 1 | L14: =IF(E14="","",SUMIFS(Resultados!$O$2:$O$401,Resultados!$D$2:$D$401,$A14,Resultados!$B$2:$B$401,$F$3,Resultados!$C$2:$C$401,E14,Resultados!$U$2:$U$401,1)) -> 1 | M14: =IF(E14="","",SUMIFS(Resultados!$P$2:$P$401,Resultados!$D$2:$D$401,$A14,Resultados!$B$2:$B$401,$F$3,Resultados!$C$2:$C$401,E14,Resultados!$U$2:$U$401,1)) -> 1 | N14: =IF(E14="","",SUMIFS(Resultados!$Q$2:$Q$401,Resultados!$D$2:$D$401,$A14,Resultados!$B$2:$B$401,$F$3,Resultados!$C$2:$C$401,E14,Resultados!$U$2:$U$401,1)) -> 1
A15: =Unidades!B11 -> CAPS Adulto | B15: =Unidades!C11 -> Centro de Atenção Psicossocial (CAPS) | C15: =IF(_xlfn.MAXIFS(Resultados!$C$2:$C$401,Resultados!$D$2:$D$401,$A15,Resultados!$B$2:$B$401,$C$3,Resultados!$U$2:$U$401,1)=0,"",_xlfn.MAXIFS(Resultados!$C$2:$C$401,Resultados!$D$2:$D$401,$A15,Resultados!$B$2:$B$401,$C$3,Resultados!$U$2:$U$401,1)) | D15: =IF(C15="","",SUMIFS(Resultados!$R$2:$R$401,Resultados!$D$2:$D$401,$A15,Resultados!$B$2:$B$401,$C$3,Resultados!$C$2:$C$401,C15,Resultados!$U$2:$U$401,1)) | E15: =IF(_xlfn.MAXIFS(Resultados!$C$2:$C$401,Resultados!$D$2:$D$401,$A15,Resultados!$B$2:$B$401,$F$3,Resultados!$U$2:$U$401,1)=0,"",_xlfn.MAXIFS(Resultados!$C$2:$C$401,Resultados!$D$2:$D$401,$A15,Resultados!$B$2:$B$401,$F$3,Resultados!$U$2:$U$401,1)) -> 46094 | F15: =IF(E15="","",SUMIFS(Resultados!$R$2:$R$401,Resultados!$D$2:$D$401,$A15,Resultados!$B$2:$B$401,$F$3,Resultados!$C$2:$C$401,E15,Resultados!$U$2:$U$401,1)) -> 0.74553571 | G15: =IF(OR(D15="",F15=""),"",(F15-D15)*100) | H15: =IF(_xlfn.MAXIFS(Resultados!$C$2:$C$401,Resultados!$D$2:$D$401,$A15,Resultados!$U$2:$U$401,1)=0,"",_xlfn.MAXIFS(Resultados!$C$2:$C$401,Resultados!$D$2:$D$401,$A15,Resultados!$U$2:$U$401,1)) -> 46094 | I15: =IF(H15="","",EDATE(H15,Unidades!F11)) -> 46278 | J15: =IF(Unidades!E11<>"ativa","suspensa",IF(H15="","sem visita",IF(I15<$K$3,"atrasada",IF(I15<=$K$3+30,"próximos 30 dias","em dia")))) -> atrasada | K15: =IF(E15="","",SUMIFS(Resultados!$N$2:$N$401,Resultados!$D$2:$D$401,$A15,Resultados!$B$2:$B$401,$F$3,Resultados!$C$2:$C$401,E15,Resultados!$U$2:$U$401,1)) -> 0.85714286 | L15: =IF(E15="","",SUMIFS(Resultados!$O$2:$O$401,Resultados!$D$2:$D$401,$A15,Resultados!$B$2:$B$401,$F$3,Resultados!$C$2:$C$401,E15,Resultados!$U$2:$U$401,1)) -> 0.875 | M15: =IF(E15="","",SUMIFS(Resultados!$P$2:$P$401,Resultados!$D$2:$D$401,$A15,Resultados!$B$2:$B$401,$F$3,Resultados!$C$2:$C$401,E15,Resultados!$U$2:$U$401,1)) -> 0.5 | N15: =IF(E15="","",SUMIFS(Resultados!$Q$2:$Q$401,Resultados!$D$2:$D$401,$A15,Resultados!$B$2:$B$401,$F$3,Resultados!$C$2:$C$401,E15,Resultados!$U$2:$U$401,1)) -> 0.75
A16: =Unidades!B12 -> UBS Mathiensen | B16: =Unidades!C12 -> Unidade Básica de Saúde (UBS) | C16: =IF(_xlfn.MAXIFS(Resultados!$C$2:$C$401,Resultados!$D$2:$D$401,$A16,Resultados!$B$2:$B$401,$C$3,Resultados!$U$2:$U$401,1)=0,"",_xlfn.MAXIFS(Resultados!$C$2:$C$401,Resultados!$D$2:$D$401,$A16,Resultados!$B$2:$B$401,$C$3,Resultados!$U$2:$U$401,1)) -> 45271 | D16: =IF(C16="","",SUMIFS(Resultados!$R$2:$R$401,Resultados!$D$2:$D$401,$A16,Resultados!$B$2:$B$401,$C$3,Resultados!$C$2:$C$401,C16,Resultados!$U$2:$U$401,1)) -> 0.35714286 | E16: =IF(_xlfn.MAXIFS(Resultados!$C$2:$C$401,Resultados!$D$2:$D$401,$A16,Resultados!$B$2:$B$401,$F$3,Resultados!$U$2:$U$401,1)=0,"",_xlfn.MAXIFS(Resultados!$C$2:$C$401,Resultados!$D$2:$D$401,$A16,Resultados!$B$2:$B$401,$F$3,Resultados!$U$2:$U$401,1)) -> 46125 | F16: =IF(E16="","",SUMIFS(Resultados!$R$2:$R$401,Resultados!$D$2:$D$401,$A16,Resultados!$B$2:$B$401,$F$3,Resultados!$C$2:$C$401,E16,Resultados!$U$2:$U$401,1)) -> 0.79464286 | G16: =IF(OR(D16="",F16=""),"",(F16-D16)*100) -> 43.75 | H16: =IF(_xlfn.MAXIFS(Resultados!$C$2:$C$401,Resultados!$D$2:$D$401,$A16,Resultados!$U$2:$U$401,1)=0,"",_xlfn.MAXIFS(Resultados!$C$2:$C$401,Resultados!$D$2:$D$401,$A16,Resultados!$U$2:$U$401,1)) -> 46125 | I16: =IF(H16="","",EDATE(H16,Unidades!F12)) -> 46308 | J16: =IF(Unidades!E12<>"ativa","suspensa",IF(H16="","sem visita",IF(I16<$K$3,"atrasada",IF(I16<=$K$3+30,"próximos 30 dias","em dia")))) -> próximos 30 dias | K16: =IF(E16="","",SUMIFS(Resultados!$N$2:$N$401,Resultados!$D$2:$D$401,$A16,Resultados!$B$2:$B$401,$F$3,Resultados!$C$2:$C$401,E16,Resultados!$U$2:$U$401,1)) -> 0.92857143 | L16: =IF(E16="","",SUMIFS(Resultados!$O$2:$O$401,Resultados!$D$2:$D$401,$A16,Resultados!$B$2:$B$401,$F$3,Resultados!$C$2:$C$401,E16,Resultados!$U$2:$U$401,1)) -> 0.75 | M16: =IF(E16="","",SUMIFS(Resultados!$P$2:$P$401,Resultados!$D$2:$D$401,$A16,Resultados!$B$2:$B$401,$F$3,Resultados!$C$2:$C$401,E16,Resultados!$U$2:$U$401,1)) -> 1 | N16: =IF(E16="","",SUMIFS(Resultados!$Q$2:$Q$401,Resultados!$D$2:$D$401,$A16,Resultados!$B$2:$B$401,$F$3,Resultados!$C$2:$C$401,E16,Resultados!$U$2:$U$401,1)) -> 0.5
A17: =Unidades!B13 -> UBS São Vito | B17: =Unidades!C13 -> Unidade Básica de Saúde (UBS) | C17: =IF(_xlfn.MAXIFS(Resultados!$C$2:$C$401,Resultados!$D$2:$D$401,$A17,Resultados!$B$2:$B$401,$C$3,Resultados!$U$2:$U$401,1)=0,"",_xlfn.MAXIFS(Resultados!$C$2:$C$401,Resultados!$D$2:$D$401,$A17,Resultados!$B$2:$B$401,$C$3,Resultados!$U$2:$U$401,1)) | D17: =IF(C17="","",SUMIFS(Resultados!$R$2:$R$401,Resultados!$D$2:$D$401,$A17,Resultados!$B$2:$B$401,$C$3,Resultados!$C$2:$C$401,C17,Resultados!$U$2:$U$401,1)) | E17: =IF(_xlfn.MAXIFS(Resultados!$C$2:$C$401,Resultados!$D$2:$D$401,$A17,Resultados!$B$2:$B$401,$F$3,Resultados!$U$2:$U$401,1)=0,"",_xlfn.MAXIFS(Resultados!$C$2:$C$401,Resultados!$D$2:$D$401,$A17,Resultados!$B$2:$B$401,$F$3,Resultados!$U$2:$U$401,1)) -> 46189 | F17: =IF(E17="","",SUMIFS(Resultados!$R$2:$R$401,Resultados!$D$2:$D$401,$A17,Resultados!$B$2:$B$401,$F$3,Resultados!$C$2:$C$401,E17,Resultados!$U$2:$U$401,1)) -> 1 | G17: =IF(OR(D17="",F17=""),"",(F17-D17)*100) | H17: =IF(_xlfn.MAXIFS(Resultados!$C$2:$C$401,Resultados!$D$2:$D$401,$A17,Resultados!$U$2:$U$401,1)=0,"",_xlfn.MAXIFS(Resultados!$C$2:$C$401,Resultados!$D$2:$D$401,$A17,Resultados!$U$2:$U$401,1)) -> 46189 | I17: =IF(H17="","",EDATE(H17,Unidades!F13)) -> 46372 | J17: =IF(Unidades!E13<>"ativa","suspensa",IF(H17="","sem visita",IF(I17<$K$3,"atrasada",IF(I17<=$K$3+30,"próximos 30 dias","em dia")))) -> em dia | K17: =IF(E17="","",SUMIFS(Resultados!$N$2:$N$401,Resultados!$D$2:$D$401,$A17,Resultados!$B$2:$B$401,$F$3,Resultados!$C$2:$C$401,E17,Resultados!$U$2:$U$401,1)) -> 1 | L17: =IF(E17="","",SUMIFS(Resultados!$O$2:$O$401,Resultados!$D$2:$D$401,$A17,Resultados!$B$2:$B$401,$F$3,Resultados!$C$2:$C$401,E17,Resultados!$U$2:$U$401,1)) -> 1 | M17: =IF(E17="","",SUMIFS(Resultados!$P$2:$P$401,Resultados!$D$2:$D$401,$A17,Resultados!$B$2:$B$401,$F$3,Resultados!$C$2:$C$401,E17,Resultados!$U$2:$U$401,1)) -> 1 | N17: =IF(E17="","",SUMIFS(Resultados!$Q$2:$Q$401,Resultados!$D$2:$D$401,$A17,Resultados!$B$2:$B$401,$F$3,Resultados!$C$2:$C$401,E17,Resultados!$U$2:$U$401,1)) -> 1
... A51: =Unidades!B47 -> Serviço de Transporte em Saúde | B51: =Unidades!C47 -> Apoio Diagnóstico e Terapêutico | C51: =IF(_xlfn.MAXIFS(Resultados!$C$2:$C$401,Resultados!$D$2:$D$401,$A51,Resultados!$B$2:$B$401,$C$3,Resultados!$U$2:$U$401,1)=0,"",_xlfn.MAXIFS(Resultados!$C$2:$C$401,Resultados!$D$2:$D$401,$A51,Resultados!$B$2:$B$401,$C$3,Resultados!$U$2:$U$401,1)) | D51: =IF(C51="","",SUMIFS(Resultados!$R$2:$R$401,Resultados!$D$2:$D$401,$A51,Resultados!$B$2:$B$401,$C$3,Resultados!$C$2:$C$401,C51,Resultados!$U$2:$U$401,1)) | E51: =IF(_xlfn.MAXIFS(Resultados!$C$2:$C$401,Resultados!$D$2:$D$401,$A51,Resultados!$B$2:$B$401,$F$3,Resultados!$U$2:$U$401,1)=0,"",_xlfn.MAXIFS(Resultados!$C$2:$C$401,Resultados!$D$2:$D$401,$A51,Resultados!$B$2:$B$401,$F$3,Resultados!$U$2:$U$401,1)) | F51: =IF(E51="","",SUMIFS(Resultados!$R$2:$R$401,Resultados!$D$2:$D$401,$A51,Resultados!$B$2:$B$401,$F$3,Resultados!$C$2:$C$401,E51,Resultados!$U$2:$U$401,1)) | G51: =IF(OR(D51="",F51=""),"",(F51-D51)*100) | H51: =IF(_xlfn.MAXIFS(Resultados!$C$2:$C$401,Resultados!$D$2:$D$401,$A51,Resultados!$U$2:$U$401,1)=0,"",_xlfn.MAXIFS(Resultados!$C$2:$C$401,Resultados!$D$2:$D$401,$A51,Resultados!$U$2:$U$401,1)) | I51: =IF(H51="","",EDATE(H51,Unidades!F47)) | J51: =IF(Unidades!E47<>"ativa","suspensa",IF(H51="","sem visita",IF(I51<$K$3,"atrasada",IF(I51<=$K$3+30,"próximos 30 dias","em dia")))) -> sem visita | K51: =IF(E51="","",SUMIFS(Resultados!$N$2:$N$401,Resultados!$D$2:$D$401,$A51,Resultados!$B$2:$B$401,$F$3,Resultados!$C$2:$C$401,E51,Resultados!$U$2:$U$401,1)) | L51: =IF(E51="","",SUMIFS(Resultados!$O$2:$O$401,Resultados!$D$2:$D$401,$A51,Resultados!$B$2:$B$401,$F$3,Resultados!$C$2:$C$401,E51,Resultados!$U$2:$U$401,1)) | M51: =IF(E51="","",SUMIFS(Resultados!$P$2:$P$401,Resultados!$D$2:$D$401,$A51,Resultados!$B$2:$B$401,$F$3,Resultados!$C$2:$C$401,E51,Resultados!$U$2:$U$401,1)) | N51: =IF(E51="","",SUMIFS(Resultados!$Q$2:$Q$401,Resultados!$D$2:$D$401,$A51,Resultados!$B$2:$B$401,$F$3,Resultados!$C$2:$C$401,E51,Resultados!$U$2:$U$401,1))
A53: Síntese do ciclo comparado
A54: Unidades visitadas | D54: =COUNT(F6:F51) -> 32
A55: Nota média | D55: =IFERROR(AVERAGE(F6:F51),"") -> 0.81961496
A56: Adequadas (verde) | D56: =COUNTIF(F6:F51,">="&Faixas!$C$4) -> 19
A57: Atenção (amarelo) | D57: =COUNTIFS(F6:F51,">="&Faixas!$C$3,F6:F51,"<"&Faixas!$C$4) -> 12
A58: Críticas (vermelho) | D58: =COUNTIF(F6:F51,"<"&Faixas!$C$3) -> 1
A59: Visitas atrasadas | D59: =COUNTIF(J6:J51,"atrasada") -> 11

Sheet Dimensoes
A1: Código | B1: Dimensão | C1: Peso | D1: Nº itens | E1: Pontuação máx. por item | F1: Pontos máx. da dimensão
A2: I | B2: Infraestrutura Física (prédios, equipamentos e insumos) | C2: 0.25 | D2: =COUNTIF(Itens!$B$2:$B$100,A2) -> 7 | E2: 2 | F2: =D2*E2 -> 14
A3: II | B3: Infraestrutura Humana | C3: 0.25 | D3: =COUNTIF(Itens!$B$2:$B$100,A3) -> 4 | E3: 2 | F3: =D3*E3 -> 8
A4: III | B4: Desempenho no Plano Municipal de Saúde | C4: 0.25 | D4: =COUNTIF(Itens!$B$2:$B$100,A4) -> 1 | E4: 2 | F4: =D4*E4 -> 2
A5: IV | B5: Percepção do Usuário | C5: 0.25 | D5: =COUNTIF(Itens!$B$2:$B$100,A5) -> 2 | E5: 2 | F5: =D5*E5 -> 4
B6: Total | C6: =SUM(C2:C5) -> 1 | D6: =SUM(D2:D5) -> 14 | F6: =SUM(F2:F5) -> 28

Sheet Itens
A1: Item | B1: Dimensão | C1: Nome do item indicador | D1: Meta esperada | E1: Fonte de observação | F1: Periodicidade
A2: I.1 | B2: I | C2: Infraestrutura civil | D2: Prédio novo ou reformado com paredes e tetos pintados, sem mofo, infiltrações ou goteiras | E2: Observações dos conselheiros e entrevista com o coordenador durante visita | F2: Semestral (exceto hospital - ver cronograma de visitas)
A3: I.2 | B3: I | C3: Infraestrutura elétrica | D3: Fiação elétrica em bom estado com equipamentos de manutenção de energia elétrica (no-break e/ou gerador) | E3: Observações dos conselheiros e entrevista com o coordenador durante visita | F3: Semestral (exceto hospital - ver cronograma de visitas)
A4: I.3 | B4: I | C4: Infraestrutura hidráulica | D4: Canos, calhas e esgotos sem entupimentos ou vazamentos | E4: Observações dos conselheiros e entrevista com o coordenador durante visita | F4: Semestral (exceto hospital - ver cronograma de visitas)
A5: I.4 | B5: I | C5: Infraestrutura de comunicação | D5: Disponibilidade de internet, telefones e computadores funcionantes e suficientes para todo o serviço | E5: Observações dos conselheiros e entrevista com o coordenador durante visita | F5: Semestral (exceto hospital - ver cronograma de visitas)
A6: I.5 | B6: I | C6: Equipamentos | D6: Número suficiente e condições adequadas de utilização dos equipamentos para prestação do serviço | E6: Observações dos conselheiros e entrevista com o coordenador durante visita | F6: Semestral (exceto hospital - ver cronograma de visitas)
A7: I.6 | B7: I | C7: Materiais, medicamentos e insumos | D7: Materiais e insumos em quantidade, reposição e condições de armazenamento adequadas | E7: Observações dos conselheiros e entrevista com o coordenador durante visita | F7: Semestral (exceto hospital - ver cronograma de visitas)
A8: I.7 | B8: I | C8: Conforto, limpeza e organização | D8: Ambiente agradável, organizado, sinalizado, com espaço para circulação, boa luminosidade e sem lixo espalhado pelo estabelecimento | E8: Observações dos conselheiros e entrevista com o coordenador durante visita | F8: Semestral (exceto hospital - ver cronograma de visitas)
A9: II.1 | B9: II | C9: Utilização de indicadores de gestão | D9: Disponibilidade de dados sobre número de atendimentos, capacidade de serviço, número de altas, número de pacientes cadastrados no serviço, principais queixas dos usuários, entre outros. Evidências sobre decisões da coordenação com base nesses dados. | E9: Apresentação de dados em fala do coordenador e existência de planilhas com os indicadores medidos na Unidade | F9: Semestral (exceto hospital - ver cronograma de visitas)
A10: II.2 | B10: II | C10: Dimensionamento de equipe | D10: Presença de escalas de trabalho visíveis e obedecidas pelos funcionários da Unidade com cobertura de todos os horários de atendimento | E10: Apresentação, compatibilidade com o trabalho e adequação das escalas e horários de trabalho dos funcionários do estabelecimento de saúde | F10: Semestral (exceto hospital - ver cronograma de visitas)
A11: II.3 | B11: II | C11: Execução do cronograma de capacitação da equipe de trabalho | D11: Mecanismos de Educação Permanente dos funcionários planejados e funcionantes | E11: Coordenador da Unidade tem disponível um cronograma de Educação Permanente dos funcionários planejado e realizado | F11: Semestral (exceto hospital - ver cronograma de visitas)
A12: II.4 | B12: II | C12: Disponibilidade de agendamento de consultas, exames e procedimentos | D12: Disponibilização de vagas mensais de consultas, exames ou procedimentos compatíveis com a capacidade, a demanda e a pactuação com a SMS | E12: Há um relatório com comparação do número de vagas mensais ofertadas e utilizadas com as consultas, exames ou procedimentos de responsabilidade do estabelecimento | F12: Semestral (exceto hospital - ver cronograma de visitas)
... A15: IV.2 | B15: IV | C15: Satisfação dos usuários | D15: Estabelecimento de saúde com alto nível de satisfação do usuário (NPS > 80%) | E15: Resultado de percepção do usuário a partir de entrevistas realizadas durante as visitas do COMSAUDE ao estabelecimento de saúde | F15: Semestral (exceto hospital - ver cronograma de visitas)

Sheet Faixas
A1: Cor | B1: Rótulo | C1: Limite inferior (inclusive)
A2: vermelho | B2: Crítico | C2: 0
A3: amarelo | B3: Atenção | C3: 0.4
A4: verde | B4: Adequado | C4: 0.8
A6: A planilha original usava formatação condicional com intervalos 0 a 0,40 / 0,41 a 0,79 / 0,80 a 1, que deixavam lacunas sem cor (ex.: 79,5%). Aqui os limites são contínuos.

Sheet Unidades
A1: id | B1: Unidade | C1: Tipo | D1: Aba na planilha original | E1: Situação | F1: Periodicidade (meses) | G1: Gestão | H1: Observação
A2: 1 | B2: UAD - Unidade de Atendimento Domiciliar | C2: Atenção Domiciliar | D2: UAD | E2: ativa | F2: 6
A3: 2 | B3: UBS Jardim São Paulo | C3: Unidade Básica de Saúde (UBS) | D3: UBS J. São Paulo | E3: ativa | F3: 6
A4: 3 | B4: Hospital Municipal Dr. Waldemar Tebaldi | C4: Hospital | D4: H. M.Urg. e Emerg. | E4: ativa | F4: 6 | H4: Cronograma de visitas próprio (Performance 2023, linha 41).
A5: 4 | B5: UPA Dona Rosa | C5: Urgência e Emergência | D5: UPA D. Rosa | E5: ativa | F5: 6 | H5: Verificar se corresponde à UPA São José avaliada em 2023.
A6: 5 | B6: Banco de Sangue | C6: Apoio Diagnóstico e Terapêutico | D6: Banco de Sangue | E6: ativa | F6: 6
A7: 6 | B7: UBS Parque Gramado | C7: Unidade Básica de Saúde (UBS) | D7: UBS Parque Gramado | E7: ativa | F7: 6 | H7: Situação em 2023: reforma.
A8: 7 | B8: ESF São José | C8: Estratégia Saúde da Família (ESF) | D8: ESF São José | E8: ativa | F8: 6 | H8: Unidade recém reformada e entregue em novembro/2023.
A9: 8 | B9: ESF Praia Azul | C9: Estratégia Saúde da Família (ESF) | D9: ESF Praia Azul | E9: ativa | F9: 6
A10: 9 | B10: ESF Jardim Brasil | C10: Estratégia Saúde da Família (ESF) | D10: ESF Jardim Brasil | E10: ativa | F10: 6
A11: 10 | B11: CAPS Adulto | C11: Centro de Atenção Psicossocial (CAPS) | D11: Caps Adulto | E11: ativa | F11: 6 | H11: Verificar se corresponde ao CAPS Arte & Vida da lista 2023.
A12: 11 | B12: UBS Mathiensen | C12: Unidade Básica de Saúde (UBS) | D12: UBS Mathiensen | E12: ativa | F12: 6
A13: 12 | B13: UBS São Vito | C13: Unidade Básica de Saúde (UBS) | D13: UBS São Vito | E13: ativa | F13: 6 | H13: Situação em 2023: reforma.
A14: 13 | B14: CAPS Infantil Larissa de Almeida | C14: Centro de Atenção Psicossocial (CAPS) | D14: Caps Infantil | E14: ativa | F14: 6
A15: 14 | B15: UBS Parque das Nações | C15: Unidade Básica de Saúde (UBS) | D15: UBS Parque das Nações | E15: ativa | F15: 6 | H15: Situação em 2023: reforma.
A16: 15 | B16: ESF Liberdade | C16: Estratégia Saúde da Família (ESF) | D16: ESF Liberdade | E16: ativa | F16: 6 | H16: Situação em 2023: reforma.
A17: 16 | B17: ESF Jaguari | C17: Estratégia Saúde da Família (ESF) | D17: ESF Jaguari | E17: ativa | F17: 6 | H17: Situação em 2023: reforma.
A18: 17 | B18: ESF Zanaga I | C18: Estratégia Saúde da Família (ESF) | D18: ESF Zanaga I | E18: ativa | F18: 6
A19: 18 | B19: ESF Zanaga II | C19: Estratégia Saúde da Família (ESF) | D19: ESF Zanaga II | E19: ativa | F19: 6
A20: 19 | B20: ADAM | C20: Entidade Parceira / Conveniada | D20: ADAM | E20: ativa | F20: 6
A21: 20 | B21: AEPHIVA | C21: Entidade Parceira / Conveniada | D21: AEPHIVA | E21: ativa | F21: 6 | H21: Visita extraordinária registrada a partir de ago/2023.
A22: 21 | B22: UBS Cariobinha | C22: Unidade Básica de Saúde (UBS) | D22: UBS Cariobinha | E22: ativa | F22: 6 | H22: Unidade recém reformada e entregue em dezembro/2023.
A23: 22 | B23: UNACON - Unidade de Oncologia | C23: Atenção Especializada | D23: UNACON | E23: ativa | F23: 6
A24: 23 | B24: APAE | C24: Entidade Parceira / Conveniada | D24: APAE | E24: ativa | F24: 6 | H24: Visita extraordinária registrada a partir de ago/2023.
A25: 24 | B25: UVISA - Vigilância Sanitária | C25: Vigilância em Saúde | D25: UVISA | E25: ativa | F25: 6
A26: 25 | B26: SAE/DST | C26: Atenção Especializada | D26: SAE DST | E26: ativa | F26: 6 | H26: Itens de percepção do usuário não se aplicam (sigilo).
A27: 26 | B27: Clínica Jones | C27: A classificar | D27: Clínica Jones | E27: ativa | F27: 6
A28: 27 | B28: UBS Vila Gallo | C28: Unidade Básica de Saúde (UBS) | D28: UBS Vila Gallo | E28: ativa | F28: 6
A29: 28 | B29: CCZ - Centro de Controle de Zoonoses | C29: Vigilância em Saúde | D29: CCZ | E29: ativa | F29: 6
A30: 29 | B30: CTA - Centro de Testagem e Aconselhamento | C30: Atenção Especializada | D30: CTA | E30: ativa | F30: 6
A31: 30 | B31: UBS Jardim Ipiranga | C31: Unidade Básica de Saúde (UBS) | D31: UBS Jardim Ipiranga | E31: ativa | F31: 6
A32: 31 | B32: CAPS AD Vida Nova (Álcool e Drogas) | C32: Centro de Atenção Psicossocial (CAPS) | D32: CAPS Alcool e Drogas | E32: ativa | F32: 6
A33: 32 | B33: PA Antonio Zanaga | C33: Urgência e Emergência | D33: PA Zanaga | E33: ativa | F33: 6 | H33: Denominada UPA Bairro Antonio Zanaga em 2023.
A34: 33 | B34: UBS Dona Rosa | C34: Unidade Básica de Saúde (UBS) | D34: UBS Dona Rosa | E34: ativa | F34: 6
A35: 34 | B35: UBS Jardim Boer | C35: Unidade Básica de Saúde (UBS) | D35: UBS Jd Boer | E35: ativa | F35: 6
A36: 35 | B36: ESF Alvorada | C36: Estratégia Saúde da Família (ESF) | D36: ESF Alvorada | E36: ativa | F36: 6
A37: 36 | B37: ESF Mário Covas | C37: Estratégia Saúde da Família (ESF) | D37: ESF Mário Covas | E37: ativa | F37: 6
A38: 37 | B38: Núcleo de Especialidades de Americana | C38: Atenção Especializada | D38: Núcleo Especialidades | E38: ativa | F38: 6
A39: 38 | B39: UBS São Domingos | C39: Unidade Básica de Saúde (UBS) | D39: UBS São Domingos | E39: ativa | F39: 6
A40: 39 | B40: UBS Guanabara | C40: Unidade Básica de Saúde (UBS) | D40: UBS Guanabara | E40: ativa | F40: 6
...

Sheet Visitas
A1: id | B1: Unidade | C1: Ciclo | D1: Data da visita | E1: Data aproximada | F1: Situação | G1: Origem | H1: Observação da importação
A2: 1 | B2: UBS Jardim Boer | C2: 2023 | D2: 45251 | E2: não | F2: concluida | G2: Planilha: Performance Unidades 2023 (linha 7) + Avaliação Global
A3: 2 | B3: UBS Jardim Ipiranga | C3: 2023 | D3: 45271 | E3: não | F3: concluida | G3: Planilha: Performance Unidades 2023 (linha 8) + Avaliação Global
A4: 3 | B4: UBS Jardim São Paulo | C4: 2023 | D4: 45231 | E4: sim | F4: concluida | G4: Planilha: Performance Unidades 2023 (linha 9) + Avaliação Global | H4: Data registrada como "nov/23??" na Performance 2023; dia aproximado. Pontuação recuperada da Avaliação Global; na Performance 2023 a linha apresentava erro de referência (fórmula quebrada).
A5: 4 | B5: UBS Dona Rosa | C5: 2023 | D5: 45229 | E5: não | F5: concluida | G5: Planilha: Performance Unidades 2023 (linha 10) + Avaliação Global
A6: 5 | B6: UBS Guanabara | C6: 2023 | D6: 45166 | E6: não | F6: concluida | G6: Planilha: Performance Unidades 2023 (linha 11) + Avaliação Global
A7: 6 | B7: UBS Mathiensen | C7: 2023 | D7: 45271 | E7: não | F7: concluida | G7: Planilha: Performance Unidades 2023 (linha 12) + Avaliação Global
A8: 7 | B8: UBS São Domingos | C8: 2023 | D8: 45104 | E8: não | F8: concluida | G8: Planilha: Performance Unidades 2023 (linha 15) + Avaliação Global
A9: 8 | B9: UBS Cariobinha | C9: 2023 | D9: 45268 | E9: não | F9: incompleta | G9: Planilha: Performance Unidades 2023 (linha 17) + Avaliação Global | H9: 7 item(ns) sem pontuação na origem.
A10: 9 | B10: UBS Vila Gallo | C10: 2023 | D10: 45159 | E10: não | F10: concluida | G10: Planilha: Performance Unidades 2023 (linha 18) + Avaliação Global | H10: Item III.1 com duas marcações na Avaliação Global (0 e 1); adotado 1, conforme Performance 2023.
A11: 10 | B11: ESF Alvorada | C11: 2023 | D11: 45124 | E11: não | F11: incompleta | G11: Planilha: Performance Unidades 2023 (linha 19) + Avaliação Global | H11: 10 item(ns) sem pontuação na origem.
A12: 11 | B12: ESF Mário Covas | C12: 2023 | D12: 45229 | E12: não | F12: concluida | G12: Planilha: Performance Unidades 2023 (linha 23) + Avaliação Global
A13: 12 | B13: ESF São José | C13: 2023 | D13: 45254 | E13: não | F13: incompleta | G13: Planilha: Performance Unidades 2023 (linha 25) + Avaliação Global | H13: Apenas a dimensão Infraestrutura Física foi avaliada (14 de 14 pontos); itens reconstruídos com nota máxima. 7 item(ns) sem pontuação na origem.
A14: 13 | B14: UAD - Unidade de Atendimento Domiciliar | C14: 2023 | D14: 45106 | E14: não | F14: concluida | G14: Planilha: Performance Unidades 2023 (linha 27) + Avaliação Global
A15: 14 | B15: CAPS AD Vida Nova (Álcool e Drogas) | C15: 2023 | D15: 45257 | E15: não | F15: concluida | G15: Planilha: Performance Unidades 2023 (linha 29) + Avaliação Global | H15: Performance 2023 registrava 21/11/2023; adotada a data 27/11/2023 da aba da unidade.
A16: 15 | B16: Núcleo de Especialidades de Americana | C16: 2023 | D16: 45124 | E16: não | F16: concluida | G16: Planilha: Performance Unidades 2023 (linha 32) + Avaliação Global
A17: 16 | B17: UPA São José | C17: 2023 | D17: 45222 | E17: não | F17: concluida | G17: Planilha: Performance Unidades 2023 (linha 33) + Avaliação Global | H17: Item III.1 = 0 na Avaliação Global, mas a Performance 2023 registrava 1 ponto (50%) digitado manualmente; mantido o valor do item.
A18: 17 | B18: PA Antonio Zanaga | C18: 2023 | D18: 45198 | E18: não | F18: incompleta | G18: Planilha: Performance Unidades 2023 (linha 34) + Avaliação Global | H18: 1 item(ns) sem pontuação na origem.
A19: 18 | B19: UNACON - Unidade de Oncologia | C19: 2023 | D19: 45268 | E19: não | F19: concluida | G19: Planilha: Performance Unidades 2023 (linha 35) + Avaliação Global | H19: Performance 2023 registrava "agosto??"; adotada a data 08/12/2023 da aba UNACON, que traz as mesmas notas.
A20: 19 | B20: CCZ - Centro de Controle de Zoonoses | C20: 2023 | D20: 45162 | E20: não | F20: concluida | G20: Planilha: Performance Unidades 2023 (linha 38) + Avaliação Global | H20: Item III.1 com duas marcações na Avaliação Global (0 e 1); adotado 1, conforme Performance 2023. Comentário de percepção do usuário idêntico ao da UNACON na Performance 2023 (provável cópia).
A21: 20 | B21: CTA - Centro de Testagem e Aconselhamento | C21: 2023 | D21: 45268 | E21: não | F21: concluida | G21: Planilha: Performance Unidades 2023 (linha 39) + Avaliação Global
A22: 21 | B22: UAD - Unidade de Atendimento Domiciliar | C22: 2026 | D22: 46164 | E22: não | F22: concluida | G22: Planilha: aba "UAD" | H22: Itens IV.1 e IV.2 estavam com 2 pontos, mas o quadro-resumo marcava a dimensão como "não aplicável"; importados como não se aplica.
A23: 22 | B23: UBS Jardim São Paulo | C23: 2026 | D23: 46090 | E23: não | F23: concluida | G23: Planilha: aba "UBS J. São Paulo"
A24: 23 | B24: Hospital Municipal Dr. Waldemar Tebaldi | C24: 2026 | D24: 46091 | E24: não | F24: concluida | G24: Planilha: aba "H. M.Urg. e Emerg."
A25: 24 | B25: UPA Dona Rosa | C25: 2026 | D25: 46093 | E25: não | F25: concluida | G25: Planilha: aba "UPA D. Rosa"
A26: 25 | B26: Banco de Sangue | C26: 2026 | D26: 46122 | E26: não | F26: concluida | G26: Planilha: aba "Banco de Sangue"
A27: 26 | B27: UBS Parque Gramado | C27: 2026 | D27: 46156 | E27: não | F27: concluida | G27: Planilha: aba "UBS Parque Gramado"
A28: 27 | B28: ESF São José | C28: 2026 | D28: 46142 | E28: não | F28: concluida | G28: Planilha: aba "ESF São José" | H28: Cabeçalho do quadro-resumo da aba indicava "ESF SÃO VITO" (erro de cópia).
A29: 28 | B29: ESF Praia Azul | C29: 2026 | D29: 46190 | E29: não | F29: concluida | G29: Planilha: aba "ESF Praia Azul"
A30: 29 | B30: ESF Jardim Brasil | C30: 2026 | D30: 46162 | E30: não | F30: concluida | G30: Planilha: aba "ESF Jardim Brasil"
A31: 30 | B31: CAPS Adulto | C31: 2026 | D31: 46094 | E31: não | F31: concluida | G31: Planilha: aba "Caps Adulto"
A32: 31 | B32: UBS Mathiensen | C32: 2026 | D32: 46125 | E32: não | F32: concluida | G32: Planilha: aba "UBS Mathiensen"
A33: 32 | B33: UBS São Vito | C33: 2026 | D33: 46189 | E33: não | F33: concluida | G33: Planilha: aba "UBS São Vito"
A34: 33 | B34: CAPS Infantil Larissa de Almeida | C34: 2026 | D34: 46234 | E34: não | F34: concluida | G34: Planilha: aba "Caps Infantil"
A35: 34 | B35: UBS Parque das Nações | C35: 2026 | D35: 46254 | E35: não | F35: concluida | G35: Planilha: aba "UBS Parque das Nações"
A36: 35 | B36: ESF Liberdade | C36: 2026 | D36: 46240 | E36: não | F36: concluida | G36: Planilha: aba "ESF Liberdade"
A37: 36 | B37: ESF Jaguari | C37: 2026 | D37: 46258 | E37: não | F37: concluida | G37: Planilha: aba "ESF Jaguari"
A38: 37 | B38: ESF Zanaga I | C38: 2026 | D38: 46239 | E38: não | F38: concluida | G38: Planilha: aba "ESF Zanaga I"
A39: 38 | B39: UBS Cariobinha | C39: 2026 | D39: 46254 | E39: não | F39: concluida | G39: Planilha: aba "UBS Cariobinha"
A40: 39 | B40: SAE/DST | C40: 2026 | D40: 46191 | E40: não | F40: concluida | G40: Planilha: aba "SAE DST" | H40: Percepção do usuário não se aplica em respeito ao sigilo.
...

Sheet Avaliacoes
A1: visita_id | B1: Unidade (conferência) | C1: Item | D1: Nome do item | E1: Ciclo (conferência) | F1: Dimensão | G1: Pontuação (0 a 2) | H1: Não se aplica (1/0)
A2: 1 | B2: =IFERROR(INDEX(Visitas!$B$2:$B$401,MATCH(A2,Visitas!$A$2:$A$401,0)),"") -> UBS Jardim Boer | C2: I.1 | D2: =IFERROR(INDEX(Itens!$C$2:$C$100,MATCH(C2,Itens!$A$2:$A$100,0)),"") -> Infraestrutura civil | E2: =IFERROR(INDEX(Visitas!$C$2:$C$401,MATCH(A2,Visitas!$A$2:$A$401,0)),"") -> 2023 | F2: =IFERROR(INDEX(Itens!$B$2:$B$100,MATCH(C2,Itens!$A$2:$A$100,0)),"") -> I | G2: 1 | H2: 0
A3: 1 | B3: =IFERROR(INDEX(Visitas!$B$2:$B$401,MATCH(A3,Visitas!$A$2:$A$401,0)),"") -> UBS Jardim Boer | C3: I.2 | D3: =IFERROR(INDEX(Itens!$C$2:$C$100,MATCH(C3,Itens!$A$2:$A$100,0)),"") -> Infraestrutura elétrica | E3: =IFERROR(INDEX(Visitas!$C$2:$C$401,MATCH(A3,Visitas!$A$2:$A$401,0)),"") -> 2023 | F3: =IFERROR(INDEX(Itens!$B$2:$B$100,MATCH(C3,Itens!$A$2:$A$100,0)),"") -> I | G3: 1 | H3: 0
A4: 1 | B4: =IFERROR(INDEX(Visitas!$B$2:$B$401,MATCH(A4,Visitas!$A$2:$A$401,0)),"") -> UBS Jardim Boer | C4: I.3 | D4: =IFERROR(INDEX(Itens!$C$2:$C$100,MATCH(C4,Itens!$A$2:$A$100,0)),"") -> Infraestrutura hidráulica | E4: =IFERROR(INDEX(Visitas!$C$2:$C$401,MATCH(A4,Visitas!$A$2:$A$401,0)),"") -> 2023 | F4: =IFERROR(INDEX(Itens!$B$2:$B$100,MATCH(C4,Itens!$A$2:$A$100,0)),"") -> I | G4: 1 | H4: 0
A5: 1 | B5: =IFERROR(INDEX(Visitas!$B$2:$B$401,MATCH(A5,Visitas!$A$2:$A$401,0)),"") -> UBS Jardim Boer | C5: I.4 | D5: =IFERROR(INDEX(Itens!$C$2:$C$100,MATCH(C5,Itens!$A$2:$A$100,0)),"") -> Infraestrutura de comunicação | E5: =IFERROR(INDEX(Visitas!$C$2:$C$401,MATCH(A5,Visitas!$A$2:$A$401,0)),"") -> 2023 | F5: =IFERROR(INDEX(Itens!$B$2:$B$100,MATCH(C5,Itens!$A$2:$A$100,0)),"") -> I | G5: 2 | H5: 0
A6: 1 | B6: =IFERROR(INDEX(Visitas!$B$2:$B$401,MATCH(A6,Visitas!$A$2:$A$401,0)),"") -> UBS Jardim Boer | C6: I.5 | D6: =IFERROR(INDEX(Itens!$C$2:$C$100,MATCH(C6,Itens!$A$2:$A$100,0)),"") -> Equipamentos | E6: =IFERROR(INDEX(Visitas!$C$2:$C$401,MATCH(A6,Visitas!$A$2:$A$401,0)),"") -> 2023 | F6: =IFERROR(INDEX(Itens!$B$2:$B$100,MATCH(C6,Itens!$A$2:$A$100,0)),"") -> I | G6: 1 | H6: 0
A7: 1 | B7: =IFERROR(INDEX(Visitas!$B$2:$B$401,MATCH(A7,Visitas!$A$2:$A$401,0)),"") -> UBS Jardim Boer | C7: I.6 | D7: =IFERROR(INDEX(Itens!$C$2:$C$100,MATCH(C7,Itens!$A$2:$A$100,0)),"") -> Materiais, medicamentos e insumos | E7: =IFERROR(INDEX(Visitas!$C$2:$C$401,MATCH(A7,Visitas!$A$2:$A$401,0)),"") -> 2023 | F7: =IFERROR(INDEX(Itens!$B$2:$B$100,MATCH(C7,Itens!$A$2:$A$100,0)),"") -> I | G7: 1 | H7: 0
A8: 1 | B8: =IFERROR(INDEX(Visitas!$B$2:$B$401,MATCH(A8,Visitas!$A$2:$A$401,0)),"") -> UBS Jardim Boer | C8: I.7 | D8: =IFERROR(INDEX(Itens!$C$2:$C$100,MATCH(C8,Itens!$A$2:$A$100,0)),"") -> Conforto, limpeza e organização | E8: =IFERROR(INDEX(Visitas!$C$2:$C$401,MATCH(A8,Visitas!$A$2:$A$401,0)),"") -> 2023 | F8: =IFERROR(INDEX(Itens!$B$2:$B$100,MATCH(C8,Itens!$A$2:$A$100,0)),"") -> I | G8: 2 | H8: 0
A9: 1 | B9: =IFERROR(INDEX(Visitas!$B$2:$B$401,MATCH(A9,Visitas!$A$2:$A$401,0)),"") -> UBS Jardim Boer | C9: II.1 | D9: =IFERROR(INDEX(Itens!$C$2:$C$100,MATCH(C9,Itens!$A$2:$A$100,0)),"") -> Utilização de indicadores de gestão | E9: =IFERROR(INDEX(Visitas!$C$2:$C$401,MATCH(A9,Visitas!$A$2:$A$401,0)),"") -> 2023 | F9: =IFERROR(INDEX(Itens!$B$2:$B$100,MATCH(C9,Itens!$A$2:$A$100,0)),"") -> II | G9: 1 | H9: 0
A10: 1 | B10: =IFERROR(INDEX(Visitas!$B$2:$B$401,MATCH(A10,Visitas!$A$2:$A$401,0)),"") -> UBS Jardim Boer | C10: II.2 | D10: =IFERROR(INDEX(Itens!$C$2:$C$100,MATCH(C10,Itens!$A$2:$A$100,0)),"") -> Dimensionamento de equipe | E10: =IFERROR(INDEX(Visitas!$C$2:$C$401,MATCH(A10,Visitas!$A$2:$A$401,0)),"") -> 2023 | F10: =IFERROR(INDEX(Itens!$B$2:$B$100,MATCH(C10,Itens!$A$2:$A$100,0)),"") -> II | G10: 2 | H10: 0
A11: 1 | B11: =IFERROR(INDEX(Visitas!$B$2:$B$401,MATCH(A11,Visitas!$A$2:$A$401,0)),"") -> UBS Jardim Boer | C11: II.3 | D11: =IFERROR(INDEX(Itens!$C$2:$C$100,MATCH(C11,Itens!$A$2:$A$100,0)),"") -> Execução do cronograma de capacitação da equipe de trabalho | E11: =IFERROR(INDEX(Visitas!$C$2:$C$401,MATCH(A11,Visitas!$A$2:$A$401,0)),"") -> 2023 | F11: =IFERROR(INDEX(Itens!$B$2:$B$100,MATCH(C11,Itens!$A$2:$A$100,0)),"") -> II | G11: 1 | H11: 0
A12: 1 | B12: =IFERROR(INDEX(Visitas!$B$2:$B$401,MATCH(A12,Visitas!$A$2:$A$401,0)),"") -> UBS Jardim Boer | C12: II.4 | D12: =IFERROR(INDEX(Itens!$C$2:$C$100,MATCH(C12,Itens!$A$2:$A$100,0)),"") -> Disponibilidade de agendamento de consultas, exames e procedimentos | E12: =IFERROR(INDEX(Visitas!$C$2:$C$401,MATCH(A12,Visitas!$A$2:$A$401,0)),"") -> 2023 | F12: =IFERROR(INDEX(Itens!$B$2:$B$100,MATCH(C12,Itens!$A$2:$A$100,0)),"") -> II | G12: 2 | H12: 0
A13: 1 | B13: =IFERROR(INDEX(Visitas!$B$2:$B$401,MATCH(A13,Visitas!$A$2:$A$401,0)),"") -> UBS Jardim Boer | C13: III.1 | D13: =IFERROR(INDEX(Itens!$C$2:$C$100,MATCH(C13,Itens!$A$2:$A$100,0)),"") -> Atendimento aos indicadores do PMS | E13: =IFERROR(INDEX(Visitas!$C$2:$C$401,MATCH(A13,Visitas!$A$2:$A$401,0)),"") -> 2023 | F13: =IFERROR(INDEX(Itens!$B$2:$B$100,MATCH(C13,Itens!$A$2:$A$100,0)),"") -> III | G13: 1 | H13: 0
... A106: 8 | B106: =IFERROR(INDEX(Visitas!$B$2:$B$401,MATCH(A106,Visitas!$A$2:$A$401,0)),"") -> UBS Cariobinha | C106: I.7 | D106: =IFERROR(INDEX(Itens!$C$2:$C$100,MATCH(C106,Itens!$A$2:$A$100,0)),"") -> Conforto, limpeza e organização | E106: =IFERROR(INDEX(Visitas!$C$2:$C$401,MATCH(A106,Visitas!$A$2:$A$401,0)),"") -> 2023 | F106: =IFERROR(INDEX(Itens!$B$2:$B$100,MATCH(C106,Itens!$A$2:$A$100,0)),"") -> I | G106: 2 | H106: 0
A107: 8 | B107: =IFERROR(INDEX(Visitas!$B$2:$B$401,MATCH(A107,Visitas!$A$2:$A$401,0)),"") -> UBS Cariobinha | C107: II.1 | D107: =IFERROR(INDEX(Itens!$C$2:$C$100,MATCH(C107,Itens!$A$2:$A$100,0)),"") -> Utilização de indicadores de gestão | E107: =IFERROR(INDEX(Visitas!$C$2:$C$401,MATCH(A107,Visitas!$A$2:$A$401,0)),"") -> 2023 | F107: =IFERROR(INDEX(Itens!$B$2:$B$100,MATCH(C107,Itens!$A$2:$A$100,0)),"") -> II | H107: 0
A108: 8 | B108: =IFERROR(INDEX(Visitas!$B$2:$B$401,MATCH(A108,Visitas!$A$2:$A$401,0)),"") -> UBS Cariobinha | C108: II.2 | D108: =IFERROR(INDEX(Itens!$C$2:$C$100,MATCH(C108,Itens!$A$2:$A$100,0)),"") -> Dimensionamento de equipe | E108: =IFERROR(INDEX(Visitas!$C$2:$C$401,MATCH(A108,Visitas!$A$2:$A$401,0)),"") -> 2023 | F108: =IFERROR(INDEX(Itens!$B$2:$B$100,MATCH(C108,Itens!$A$2:$A$100,0)),"") -> II | H108: 0
A109: 8 | B109: =IFERROR(INDEX(Visitas!$B$2:$B$401,MATCH(A109,Visitas!$A$2:$A$401,0)),"") -> UBS Cariobinha | C109: II.3 | D109: =IFERROR(INDEX(Itens!$C$2:$C$100,MATCH(C109,Itens!$A$2:$A$100,0)),"") -> Execução do cronograma de capacitação da equipe de trabalho | E109: =IFERROR(INDEX(Visitas!$C$2:$C$401,MATCH(A109,Visitas!$A$2:$A$401,0)),"") -> 2023 | F109: =IFERROR(INDEX(Itens!$B$2:$B$100,MATCH(C109,Itens!$A$2:$A$100,0)),"") -> II | H109: 0
A110: 8 | B110: =IFERROR(INDEX(Visitas!$B$2:$B$401,MATCH(A110,Visitas!$A$2:$A$401,0)),"") -> UBS Cariobinha | C110: II.4 | D110: =IFERROR(INDEX(Itens!$C$2:$C$100,MATCH(C110,Itens!$A$2:$A$100,0)),"") -> Disponibilidade de agendamento de consultas, exames e procedimentos | E110: =IFERROR(INDEX(Visitas!$C$2:$C$401,MATCH(A110,Visitas!$A$2:$A$401,0)),"") -> 2023 | F110: =IFERROR(INDEX(Itens!$B$2:$B$100,MATCH(C110,Itens!$A$2:$A$100,0)),"") -> II | H110: 0
A111: 8 | B111: =IFERROR(INDEX(Visitas!$B$2:$B$401,MATCH(A111,Visitas!$A$2:$A$401,0)),"") -> UBS Cariobinha | C111: III.1 | D111: =IFERROR(INDEX(Itens!$C$2:$C$100,MATCH(C111,Itens!$A$2:$A$100,0)),"") -> Atendimento aos indicadores do PMS | E111: =IFERROR(INDEX(Visitas!$C$2:$C$401,MATCH(A111,Visitas!$A$2:$A$401,0)),"") -> 2023 | F111: =IFERROR(INDEX(Itens!$B$2:$B$100,MATCH(C111,Itens!$A$2:$A$100,0)),"") -> III | H111: 0
A112: 8 | B112: =IFERROR(INDEX(Visitas!$B$2:$B$401,MATCH(A112,Visitas!$A$2:$A$401,0)),"") -> UBS Cariobinha | C112: IV.1 | D112: =IFERROR(INDEX(Itens!$C$2:$C$100,MATCH(C112,Itens!$A$2:$A$100,0)),"") -> Registro de reclamações na Ouvidoria do COMSAUDE | E112: =IFERROR(INDEX(Visitas!$C$2:$C$401,MATCH(A112,Visitas!$A$2:$A$401,0)),"") -> 2023 | F112: =IFERROR(INDEX(Itens!$B$2:$B$100,MATCH(C112,Itens!$A$2:$A$100,0)),"") -> IV | H112: 0
A113: 8 | B113: =IFERROR(INDEX(Visitas!$B$2:$B$401,MATCH(A113,Visitas!$A$2:$A$401,0)),"") -> UBS Cariobinha | C113: IV.2 | D113: =IFERROR(INDEX(Itens!$C$2:$C$100,MATCH(C113,Itens!$A$2:$A$100,0)),"") -> Satisfação dos usuários | E113: =IFERROR(INDEX(Visitas!$C$2:$C$401,MATCH(A113,Visitas!$A$2:$A$401,0)),"") -> 2023 | F113: =IFERROR(INDEX(Itens!$B$2:$B$100,MATCH(C113,Itens!$A$2:$A$100,0)),"") -> IV | H113: 0
A114: 9 | B114: =IFERROR(INDEX(Visitas!$B$2:$B$401,MATCH(A114,Visitas!$A$2:$A$401,0)),"") -> UBS Vila Gallo | C114: I.1 | D114: =IFERROR(INDEX(Itens!$C$2:$C$100,MATCH(C114,Itens!$A$2:$A$100,0)),"") -> Infraestrutura civil | E114: =IFERROR(INDEX(Visitas!$C$2:$C$401,MATCH(A114,Visitas!$A$2:$A$401,0)),"") -> 2023 | F114: =IFERROR(INDEX(Itens!$B$2:$B$100,MATCH(C114,Itens!$A$2:$A$100,0)),"") -> I | G114: 1 | H114: 0
A115: 9 | B115: =IFERROR(INDEX(Visitas!$B$2:$B$401,MATCH(A115,Visitas!$A$2:$A$401,0)),"") -> UBS Vila Gallo | C115: I.2 | D115: =IFERROR(INDEX(Itens!$C$2:$C$100,MATCH(C115,Itens!$A$2:$A$100,0)),"") -> Infraestrutura elétrica | E115: =IFERROR(INDEX(Visitas!$C$2:$C$401,MATCH(A115,Visitas!$A$2:$A$401,0)),"") -> 2023 | F115: =IFERROR(INDEX(Itens!$B$2:$B$100,MATCH(C115,Itens!$A$2:$A$100,0)),"") -> I | G115: 2 | H115: 0
A116: 9 | B116: =IFERROR(INDEX(Visitas!$B$2:$B$401,MATCH(A116,Visitas!$A$2:$A$401,0)),"") -> UBS Vila Gallo | C116: I.3 | D116: =IFERROR(INDEX(Itens!$C$2:$C$100,MATCH(C116,Itens!$A$2:$A$100,0)),"") -> Infraestrutura hidráulica | E116: =IFERROR(INDEX(Visitas!$C$2:$C$401,MATCH(A116,Visitas!$A$2:$A$401,0)),"") -> 2023 | F116: =IFERROR(INDEX(Itens!$B$2:$B$100,MATCH(C116,Itens!$A$2:$A$100,0)),"") -> I | G116: 1 | H116: 0
A117: 9 | B117: =IFERROR(INDEX(Visitas!$B$2:$B$401,MATCH(A117,Visitas!$A$2:$A$401,0)),"") -> UBS Vila Gallo | C117: I.4 | D117: =IFERROR(INDEX(Itens!$C$2:$C$100,MATCH(C117,Itens!$A$2:$A$100,0)),"") -> Infraestrutura de comunicação | E117: =IFERROR(INDEX(Visitas!$C$2:$C$401,MATCH(A117,Visitas!$A$2:$A$401,0)),"") -> 2023 | F117: =IFERROR(INDEX(Itens!$B$2:$B$100,MATCH(C117,Itens!$A$2:$A$100,0)),"") -> I | G117: 2 | H117: 0
A118: 9 | B118: =IFERROR(INDEX(Visitas!$B$2:$B$401,MATCH(A118,Visitas!$A$2:$A$401,0)),"") -> UBS Vila Gallo | C118: I.5 | D118: =IFERROR(INDEX(Itens!$C$2:$C$100,MATCH(C118,Itens!$A$2:$A$100,0)),"") -> Equipamentos | E118: =IFERROR(INDEX(Visitas!$C$2:$C$401,MATCH(A118,Visitas!$A$2:$A$401,0)),"") -> 2023 | F118: =IFERROR(INDEX(Itens!$B$2:$B$100,MATCH(C118,Itens!$A$2:$A$100,0)),"") -> I | G118: 2 | H118: 0
A119: 9 | B119: =IFERROR(INDEX(Visitas!$B$2:$B$401,MATCH(A119,Visitas!$A$2:$A$401,0)),"") -> UBS Vila Gallo | C119: I.6 | D119: =IFERROR(INDEX(Itens!$C$2:$C$100,MATCH(C119,Itens!$A$2:$A$100,0)),"") -> Materiais, medicamentos e insumos | E119: =IFERROR(INDEX(Visitas!$C$2:$C$401,MATCH(A119,Visitas!$A$2:$A$401,0)),"") -> 2023 | F119: =IFERROR(INDEX(Itens!$B$2:$B$100,MATCH(C119,Itens!$A$2:$A$100,0)),"") -> I | G119: 2 | H119: 0
A120: 9 | B120: =IFERROR(INDEX(Visitas!$B$2:$B$401,MATCH(A120,Visitas!$A$2:$A$401,0)),"") -> UBS Vila Gallo | C120: I.7 | D120: =IFERROR(INDEX(Itens!$C$2:$C$100,MATCH(C120,Itens!$A$2:$A$100,0)),"") -> Conforto, limpeza e organização | E120: =IFERROR(INDEX(Visitas!$C$2:$C$401,MATCH(A120,Visitas!$A$2:$A$401,0)),"") -> 2023 | F120: =IFERROR(INDEX(Itens!$B$2:$B$100,MATCH(C120,Itens!$A$2:$A$100,0)),"") -> I | G120: 2 | H120: 0
A121: 9 | B121: =IFERROR(INDEX(Visitas!$B$2:$B$401,MATCH(A121,Visitas!$A$2:$A$401,0)),"") -> UBS Vila Gallo | C121: II.1 | D121: =IFERROR(INDEX(Itens!$C$2:$C$100,MATCH(C121,Itens!$A$2:$A$100,0)),"") -> Utilização de indicadores de gestão | E121: =IFERROR(INDEX(Visitas!$C$2:$C$401,MATCH(A121,Visitas!$A$2:$A$401,0)),"") -> 2023 | F121: =IFERROR(INDEX(Itens!$B$2:$B$100,MATCH(C121,Itens!$A$2:$A$100,0)),"") -> II | G121: 1 | H121: 0
A122: 9 | B122: =IFERROR(INDEX(Visitas!$B$2:$B$401,MATCH(A122,Visitas!$A$2:$A$401,0)),"") -> UBS Vila Gallo | C122: II.2 | D122: =IFERROR(INDEX(Itens!$C$2:$C$100,MATCH(C122,Itens!$A$2:$A$100,0)),"") -> Dimensionamento de equipe | E122: =IFERROR(INDEX(Visitas!$C$2:$C$401,MATCH(A122,Visitas!$A$2:$A$401,0)),"") -> 2023 | F122: =IFERROR(INDEX(Itens!$B$2:$B$100,MATCH(C122,Itens!$A$2:$A$100,0)),"") -> II | G122: 2 | H122: 0
A123: 9 | B123: =IFERROR(INDEX(Visitas!$B$2:$B$401,MATCH(A123,Visitas!$A$2:$A$401,0)),"") -> UBS Vila Gallo | C123: II.3 | D123: =IFERROR(INDEX(Itens!$C$2:$C$100,MATCH(C123,Itens!$A$2:$A$100,0)),"") -> Execução do cronograma de capacitação da equipe de trabalho | E123: =IFERROR(INDEX(Visitas!$C$2:$C$401,MATCH(A123,Visitas!$A$2:$A$401,0)),"") -> 2023 | F123: =IFERROR(INDEX(Itens!$B$2:$B$100,MATCH(C123,Itens!$A$2:$A$100,0)),"") -> II | G123: 2 | H123: 0
