Workbook

Sheet UAD
A1: Dimensões e itens para avaliação global de desempenho dos estabelecimentos municipais de saúde
A3: Dimensões | B3: ID item indicador | C3: Nome do item indicador | D3: Meta esperada no item indicador | E3: Fonte de observação do dado | F3: Periodicidade de observação | G3: Pontuação mínima por item | H3: Pontuação média por item | I3: Pontuação máxima por item | J3: Pontuação por dimensão
A4: I. Infraestrutura Física | B4: I.1 | C4: Infraestrutura civil | D4: Prédio novo ou reformado com paredes e tetos pintados, sem mofo, infiltrações ou goteiras | E4: Observações dos conselheiros e entrevista com o coordenador durante visita | F4: Semestral (exceto hospital - ver cronograma de visitas) | I4: 2 | J4: =SUM(G4:I10) -> 14
A5: I. Infraestrutura Física | B5: I.2 | C5: Infraestrutura elétrica | D5: Fiação elétrica em bom estado com equipamentos de manutenção de energia elétrica (no-break e/ou gerador) | E5: Observações dos conselheiros e entrevista com o coordenador durante visita | F5: Semestral (exceto hospital - ver cronograma de visitas) | I5: 2
A6: I. Infraestrutura Física | B6: I.3 | D6: Canos, calhas e esgotos sem entupimentos ou vazamentos | E6: Observações dos conselheiros e entrevista com o coordenador durante visita | F6: Semestral (exceto hospital - ver cronograma de visitas) | I6: 2
A7: I. Infraestrutura Física | B7: I.4 | C7: Infraestrutura de comunicação | D7: Disponibilidade de internet, telefones e computadores funcionantes e suficientes para todo o serviço | E7: Observações dos conselheiros e entrevista com o coordenador durante visita | F7: Semestral (exceto hospital - ver cronograma de visitas) | I7: 2
A8: I. Infraestrutura Física | B8: I.5 | C8: Equipamentos | D8: Número suficiente e condições adequadas de utilização dos equipamentos para prestação do serviço | E8: Observações dos conselheiros e entrevista com o coordenador durante visita | F8: Semestral (exceto hospital - ver cronograma de visitas) | I8: 2
A9: I. Infraestrutura Física | B9: I.6 | C9: Materiais, medicamentos e insumos | D9: Materiais e insumos em quantidade, reposição e condições de armazenamento adequadas | E9: Observações dos conselheiros e entrevista com o coordenador durante visita | F9: Semestral (exceto hospital - ver cronograma de visitas) | I9: 2
A10: I. Infraestrutura Física | B10: I.7 | C10: Conforto, limpeza e organização | D10: Ambiente agradável, organizado, sinalizado, com espaço para circulação, boa luminosidade e sem lixo espalhado pelo estabelecimento | E10: Observações dos conselheiros e entrevista com o coordenador durante visita | F10: Semestral (exceto hospital - ver cronograma de visitas) | I10: 2
A11: II. Infraestrutura Humana | B11: II.1 | C11: Utilização de indicadores de gestão | D11: Disponibilidade de dados sobre número de atendimentos, capacidade de serviço, número de altas, número de pacientes cadastrados no serviço, principais queixas dos usuários, entre outros. Evidências sobre decisões da coordenação com base nesses dados. | E11: Apresentação de dados em fala do coordenador e existência de planilhas com os indicadores medidos na Unidade | F11: Semestral (exceto hospital - ver cronograma de visitas) | I11: 2 | J11: =SUM(G11:I14) -> 8
A12: II. Infraestrutura Humana | B12: II.2 | C12: Dimensionamento de equipe | D12: Presença de escalas de trabalho visíveis e obedecidas pelos funcionários da Unidade com cobertura de todos os horários de atendimento | E12: Apresentação, compatibilidade com o trabalho e adequação das escalas e horários de trabalho dos funcionários do estabelecimento de saúde | F12: Semestral (exceto hospital - ver cronograma de visitas) | I12: 2
A13: II. Infraestrutura Humana | B13: II.3 | C13: Execução do cronograma de capacitação da equipe de trabalho | D13: Mecanismos de Educação Permanente dos funcionários planejados e funcionantes | E13: Coordenador da Unidade tem disponível um cronograma de Educação Permanente dos funcionários planejado e realizado | F13: Semestral (exceto hospital - ver cronograma de visitas) | I13: 2
A14: II. Infraestrutura Humana | B14: II.4. | C14: Disponibilidade de agendamento de consultas, exames e procedimentos | D14: Disponibilização de vagas mensais de consultas, exames ou procedimentos compatíveis com a capacidade, a demanda e a pactuação com a SMS | E14: Há um relatório com comparação do número de vagas mensais ofertadas e utilizadas com as consultas, exames ou procedimentos de responsabilidade do estabelecimento | F14: Semestral (exceto hospital - ver cronograma de visitas) | I14: 2
A15: III. Desempenho no Plano Municipal de Saúde | B15: III. 1 | C15: Atendimento aos indicadores do PMS | D15: O estabelecimento de saúde demonstra o cumprimento de todos os indicadores que assumiu para o ano no Plano Municipal de Saúde | E15: Porcentagem de respostas adequadas às questões formuladas para cada indicador do Plano Municipal de Saúde | F15: Semestral | I15: 2 | J15: =SUM(G15:I15) -> 2
A16: IV. Percepção do usuário | B16: IV.1 | C16: Registro de reclamações na Ouvidoria do COMSAUDE | D16: Ausência de registros de reclamações dos usuários sobre o serviço e/ou resolução adequada de eventuais demandas de pequena gravidade existentes | E16: Relatório com número de demandas apresentadas ao COMSAUDE pelos usuários e suas resoluções | F16: Semestral | I16: 2 | J16: =SUM(G16:I17) -> 4
A17: IV. Percepção do usuário | B17: IV.2 | C17: Satisfação dos usuários | D17: Estabelecimento de saúde com alto nível de satisfação do usuário (NPS > 80%) | E17: Resultado de percepção do usuário a partir de entrevistas realizadas durante as visitas do COMSAUDE ao estabelecimento de saúde | F17: Semestral (exceto hospital - ver cronograma de visitas) | I17: 2
A18: Pontuação total daa visita realizadaa em 22/05/2026 | H18: =SUM(H4:H17) -> 0 | I18: =SUM(I4:I17) -> 28 | J18: =SUM(J4:J17) -> 28
A22: Dimensões avaliadas | B22: Número de itens pontuados | C22: Pontuação máxima possível nas dimensões analisadas | D22: Peso da dimensão | E22: UAD | F22: Pontos obtidos por dimensão (exemplo) | G22: % de execução em cada dimensão (exemplo) | H22: Pontuação final (exemplo)
A23: I - Infraestrutura física (prédios, equipamentos e insumos) | B23: 7 | C23: 14 | D23: 0.25 | F23: 14 | G23: =F23/C23 -> 1 | H23: =G23*D23 -> 0.25
A24: II - Infraestrutura humana | B24: 4 | C24: 8 | D24: 0.25 | F24: 8 | G24: =F24/C24 -> 1 | H24: =G24*D24 -> 0.25
A25: III - Desempenho no Plano Municipal de Saúde | B25: 1 | C25: 2 | D25: 0.25 | F25: 2 | G25: =F25/C25 -> 1 | H25: =G25*D25 -> 0.25
A26: IV - Percepção do usuário | B26: 2 | C26: 4 | D26: 0.25 | F26: não aplicável
A27: Totais | B27: =SUM(B23:B26) -> 14 | C27: =SUM(C23:C26) -> 28 | D27: =SUM(D23:D26) -> 1 | F27: =SUM(F23:F26) -> 24 | G27: - | H27: =SUM(H23:H26) -> 0.75

Sheet UBS J. São Paulo
A1: Dimensões e itens para avaliação global de desempenho dos estabelecimentos municipais de saúde
A3: Dimensões | B3: ID item indicador | C3: Nome do item indicador | D3: Meta esperada no item indicador | E3: Fonte de observação do dado | F3: Periodicidade de observação | G3: Pontuação mínima por item | H3: Pontuação média por item | I3: Pontuação máxima por item | J3: Pontuação por dimensão
A4: I. Infraestrutura Física | B4: I.1 | C4: Infraestrutura civil | D4: Prédio novo ou reformado com paredes e tetos pintados, sem mofo, infiltrações ou goteiras | E4: Observações dos conselheiros e entrevista com o coordenador durante visita | F4: Semestral (exceto hospital - ver cronograma de visitas) | H4: 1 | J4: =SUM(G4:I10) -> 11
A5: I. Infraestrutura Física | B5: I.2 | C5: Infraestrutura elétrica | D5: Fiação elétrica em bom estado com equipamentos de manutenção de energia elétrica (no-break e/ou gerador) | E5: Observações dos conselheiros e entrevista com o coordenador durante visita | F5: Semestral (exceto hospital - ver cronograma de visitas) | I5: 2
A6: I. Infraestrutura Física | B6: I.3 | D6: Canos, calhas e esgotos sem entupimentos ou vazamentos | E6: Observações dos conselheiros e entrevista com o coordenador durante visita | F6: Semestral (exceto hospital - ver cronograma de visitas) | H6: 1
A7: I. Infraestrutura Física | B7: I.4 | C7: Infraestrutura de comunicação | D7: Disponibilidade de internet, telefones e computadores funcionantes e suficientes para todo o serviço | E7: Observações dos conselheiros e entrevista com o coordenador durante visita | F7: Semestral (exceto hospital - ver cronograma de visitas) | I7: 2
A8: I. Infraestrutura Física | B8: I.5 | C8: Equipamentos | D8: Número suficiente e condições adequadas de utilização dos equipamentos para prestação do serviço | E8: Observações dos conselheiros e entrevista com o coordenador durante visita | F8: Semestral (exceto hospital - ver cronograma de visitas) | I8: 2
A9: I. Infraestrutura Física | B9: I.6 | C9: Materiais, medicamentos e insumos | D9: Materiais e insumos em quantidade, reposição e condições de armazenamento adequadas | E9: Observações dos conselheiros e entrevista com o coordenador durante visita | F9: Semestral (exceto hospital - ver cronograma de visitas) | I9: 2
A10: I. Infraestrutura Física | B10: I.7 | C10: Conforto, limpeza e organização | D10: Ambiente agradável, organizado, sinalizado, com espaço para circulação, boa luminosidade e sem lixo espalhado pelo estabelecimento | E10: Observações dos conselheiros e entrevista com o coordenador durante visita | F10: Semestral (exceto hospital - ver cronograma de visitas) | H10: 1
A11: II. Infraestrutura Humana | B11: II.1 | C11: Utilização de indicadores de gestão | D11: Disponibilidade de dados sobre número de atendimentos, capacidade de serviço, número de altas, número de pacientes cadastrados no serviço, principais queixas dos usuários, entre outros. Evidências sobre decisões da coordenação com base nesses dados. | E11: Apresentação de dados em fala do coordenador e existência de planilhas com os indicadores medidos na Unidade | F11: Semestral (exceto hospital - ver cronograma de visitas) | I11: 2 | J11: =SUM(G11:I14) -> 8
A12: II. Infraestrutura Humana | B12: II.2 | C12: Dimensionamento de equipe | D12: Presença de escalas de trabalho visíveis e obedecidas pelos funcionários da Unidade com cobertura de todos os horários de atendimento | E12: Apresentação, compatibilidade com o trabalho e adequação das escalas e horários de trabalho dos funcionários do estabelecimento de saúde | F12: Semestral (exceto hospital - ver cronograma de visitas) | I12: 2
A13: II. Infraestrutura Humana | B13: II.3 | C13: Execução do cronograma de capacitação da equipe de trabalho | D13: Mecanismos de Educação Permanente dos funcionários planejados e funcionantes | E13: Coordenador da Unidade tem disponível um cronograma de Educação Permanente dos funcionários planejado e realizado | F13: Semestral (exceto hospital - ver cronograma de visitas) | I13: 2
A14: II. Infraestrutura Humana | B14: II.4. | C14: Disponibilidade de agendamento de consultas, exames e procedimentos | D14: Disponibilização de vagas mensais de consultas, exames ou procedimentos compatíveis com a capacidade, a demanda e a pactuação com a SMS | E14: Há um relatório com comparação do número de vagas mensais ofertadas e utilizadas com as consultas, exames ou procedimentos de responsabilidade do estabelecimento | F14: Semestral (exceto hospital - ver cronograma de visitas) | I14: 2
A15: III. Desempenho no Plano Municipal de Saúde | B15: III. 1 | C15: Atendimento aos indicadores do PMS | D15: O estabelecimento de saúde demonstra o cumprimento de todos os indicadores que assumiu para o ano no Plano Municipal de Saúde | E15: Porcentagem de respostas adequadas às questões formuladas para cada indicador do Plano Municipal de Saúde | F15: Semestral | I15: 2 | J15: =SUM(G15:I15) -> 2
A16: IV. Percepção do usuário | B16: IV.1 | C16: Registro de reclamações na Ouvidoria do COMSAUDE | D16: Ausência de registros de reclamações dos usuários sobre o serviço e/ou resolução adequada de eventuais demandas de pequena gravidade existentes | E16: Relatório com número de demandas apresentadas ao COMSAUDE pelos usuários e suas resoluções | F16: Semestral | H16: 1 | J16: =SUM(G16:I17) -> 3
A17: IV. Percepção do usuário | B17: IV.2 | C17: Satisfação dos usuários | D17: Estabelecimento de saúde com alto nível de satisfação do usuário (NPS > 80%) | E17: Resultado de percepção do usuário a partir de entrevistas realizadas durante as visitas do COMSAUDE ao estabelecimento de saúde | F17: Semestral (exceto hospital - ver cronograma de visitas) | I17: 2
A18: Pontuação total da visita realizada em 09/03/2026 | H18: =SUM(H4:H17) -> 4 | I18: =SUM(I4:I17) -> 20 | J18: =SUM(J4:J17) -> 24
A22: Dimensões avaliadas | B22: Número de itens pontuados | C22: Pontuação máxima possível nas dimensões analisadas | D22: Peso da dimensão | E22: UBS JARDIM SÃO PAULO | F22: Pontos obtidos por dimensão (exemplo) | G22: % de execução em cada dimensão (exemplo) | H22: Pontuação final (exemplo)
A23: I - Infraestrutura física (prédios, equipamentos e insumos) | B23: 7 | C23: 14 | D23: 0.25 | F23: 11 | G23: =F23/C23 -> 0.78571429 | H23: =G23*D23 -> 0.19642857
A24: II - Infraestrutura humana | B24: 4 | C24: 8 | D24: 0.25 | F24: 8 | G24: =F24/C24 -> 1 | H24: =G24*D24 -> 0.25
A25: III - Desempenho no Plano Municipal de Saúde | B25: 1 | C25: 2 | D25: 0.25 | F25: 2 | G25: =F25/C25 -> 1 | H25: =G25*D25 -> 0.25
A26: IV - Percepção do usuário | B26: 2 | C26: 4 | D26: 0.25 | F26: 3 | G26: =F26/C26 -> 0.75 | H26: =G26*D26 -> 0.1875
A27: Totais | B27: =SUM(B23:B26) -> 14 | C27: =SUM(C23:C26) -> 28 | D27: =SUM(D23:D26) -> 1 | F27: =SUM(F23:F26) -> 24 | G27: - | H27: =SUM(H23:H26) -> 0.88392857

Sheet H. M.Urg. e Emerg.
A1: Dimensões e itens para avaliação global de desempenho dos estabelecimentos municipais de saúde
A3: Dimensões | B3: ID item indicador | C3: Nome do item indicador | D3: Meta esperada no item indicador | E3: Fonte de observação do dado | F3: Periodicidade de observação | G3: Pontuação mínima por item | H3: Pontuação média por item | I3: Pontuação máxima por item | J3: Pontuação por dimensão
A4: I. Infraestrutura Física | B4: I.1 | C4: Urgência/Emergência | D4: Rediscutir, junto à sociedade civil organizada, o desenho da atenção da Urgência/Emergência Municipal | E4: Entrevista com o gestor do HM | F4: Semestral (exceto hospital - ver cronograma de visitas) | H4: 1 | J4: =SUM(G4:I10) -> 11
A5: I. Infraestrutura Física | B5: I.2 | C5: Trabalho Integrado | D5: Há integração de protocolos entre equipes das UPAS, 192 e UBS? | E5: Observações dos conselheiros e entrevista com o coordenador durante visita | F5: Semestral (exceto hospital - ver cronograma de visitas) | I5: 2
A6: I. Infraestrutura Física | B6: I.3 | C6: Espaço Físico | D6: Espaço físico e mobiliário são adequados para o movimento? | E6: Observações dos conselheiros e entrevista com o coordenador durante visita | F6: Semestral (exceto hospital - ver cronograma de visitas) | H6: 1
A7: I. Infraestrutura Física | B7: I.4 | C7: Infraestrutura de comunicação | D7: Disponibilidade de internet, telefones e computadores funcionantes e suficientes para todo o serviço | E7: Observações dos conselheiros e entrevista com o coordenador durante visita | F7: Semestral (exceto hospital - ver cronograma de visitas) | I7: 2
A8: I. Infraestrutura Física | B8: I.5 | C8: Equipamentos | D8: Número suficiente e condições adequadas de utilização dos equipamentos para prestação do serviço | E8: Observações dos conselheiros e entrevista com o coordenador durante visita | F8: Semestral (exceto hospital - ver cronograma de visitas) | I8: 2
A9: I. Infraestrutura Física | B9: I.6 | C9: Realização de simulados sobre atendimento em acidentes com múltiplas vítimas | D9: Cronograma de treinamento junto aos colaboradores das diversas Unidades/ | E9: Periodicidade desses treinamentos é a ideal? | F9: Ver cronograma desses treinamentos | I9: 2
A10: I. Infraestrutura Física | B10: I.7 | C10: Conforto, limpeza e organização | D10: Aquisição de enxoval, periodicidade, lavanderia própria? | E10: Observações dos conselheiros e entrevista com o coordenador durante visita | F10: Semestral (exceto hospital - ver cronograma de visitas) | H10: 1
A11: II. Infraestrutura Humana | B11: II.1 | C11: Utilização de indicadores de gestão | D11: Cronograma de treinamento para Classificação de Risco | E11: Apresentação de dados relacionados a esses indicadores | F11: Semestral (exceto hospital - ver cronograma de visitas) | I11: 2 | J11: =SUM(G11:I14) -> 7
A12: II. Infraestrutura Humana | B12: II.2 | C12: Dimensionamento de equipe | D12: Presença de escalas de trabalho visíveis e obedecidas pelos funcionários da Unidade com cobertura de todos os horários de atendimento | E12: Apresentação, compatibilidade com o trabalho e adequação das escalas e horários de trabalho dos funcionários do estabelecimento de saúde | F12: Semestral (exceto hospital - ver cronograma de visitas) | I12: 2
A13: II. Infraestrutura Humana | B13: II.3 | C13: Realização de Exames | D13: Todos os exames solicitados são realizados? | F13: Semestral (exceto hospital - ver cronograma de visitas) | I13: 2
A14: II. Infraestrutura Humana | B14: II.4. | C14: Disponibilidade de agendamento de exames externos | D14: Há dificuldade quanto à realização desses exames? Tempo de espera | E14: Há um relatório quanto a isso? | F14: Semestral (exceto hospital - ver cronograma de visitas) | H14: 1
A15: III. Desempenho no Plano Municipal de Saúde | B15: III. 1 | C15: Atendimento aos indicadores do PMS | D15: O estabelecimento de saúde demonstra o cumprimento de todos os indicadores que assumiu para o ano no Plano Municipal de Saúde | E15: Porcentagem de respostas adequadas às questões formuladas para cada indicador do Plano Municipal de Saúde | F15: Semestral | H15: 1 | J15: 1
A16: IV. Percepção do usuário | B16: IV.1 | C16: Registro de reclamações na Ouvidoria do COMSAUDE | D16: Ausência de registros de reclamações dos usuários sobre o serviço e/ou resolução adequada de eventuais demandas de pequena gravidade existentes | E16: Relatório com número de demandas apresentadas ao COMSAUDE pelos usuários e suas resoluções | F16: Semestral | H16: 1 | J16: =SUM(G16:I17) -> 2
A17: IV. Percepção do usuário | B17: IV.2 | C17: Satisfação dos usuários | D17: Estabelecimento com índice bom quanto ao atendimento | E17: Resultado de percepção do usuário a partir de entrevistas realizadas durante as visitas do COMSAUDE ao estabelecimento de saúde | F17: Semestral (exceto hospital - ver cronograma de visitas) | H17: 1
A18: pontuação total da visita realizada em 10/03/2026 | H18: =SUM(H4:H17) -> 7 | I18: =SUM(I4:I17) -> 14 | J18: =SUM(J4:J17) -> 21
A22: Dimensões avaliadas | B22: Número de itens pontuados | C22: Pontuação máxima possível nas dimensões analisadas | D22: Peso da dimensão | E22: HM URGÊNCIA/EMERGÊNCIA | F22: Pontos obtidos por dimensão (exemplo) | G22: % de execução em cada dimensão (exemplo) | H22: Pontuação final (exemplo)
A23: I - Infraestrutura física (prédios, equipamentos e insumos) | B23: 7 | C23: 14 | D23: 0.25 | F23: 11 | G23: =F23/C23 -> 0.78571429 | H23: =G23*D23 -> 0.19642857
A24: II - Infraestrutura humana | B24: 4 | C24: 8 | D24: 0.25 | F24: 7 | G24: =F24/C24 -> 0.875 | H24: =G24*D24 -> 0.21875
A25: III - Desempenho no Plano Municipal de Saúde | B25: 1 | C25: 2 | D25: 0.25 | F25: 1 | G25: =F25/C25 -> 0.5 | H25: =G25*D25 -> 0.125
A26: IV - Percepção do usuário | B26: 2 | C26: 4 | D26: 0.25 | F26: 2 | G26: =F26/C26 -> 0.5 | H26: =G26*D26 -> 0.125
A27: Totais | B27: =SUM(B23:B26) -> 14 | C27: =SUM(C23:C26) -> 28 | D27: =SUM(D23:D26) -> 1 | F27: =SUM(F23:F26) -> 21 | G27: - | H27: =SUM(H23:H26) -> 0.66517857

Sheet UPA D. Rosa
A1: Dimensões e itens para avaliação global de desempenho dos estabelecimentos municipais de saúde
A3: Dimensões | B3: ID item indicador | C3: Nome do item indicador | D3: Meta esperada no item indicador | E3: Fonte de observação do dado | F3: Periodicidade de observação | G3: Pontuação mínima por item | H3: Pontuação média por item | I3: Pontuação máxima por item | J3: Pontuação por dimensão
A4: I. Infraestrutura Física | B4: I.1 | C4: Infraestrutura civil | D4: Prédio novo ou reformado com paredes e tetos pintados, sem mofo, infiltrações ou goteiras | E4: Observações dos conselheiros e entrevista com o coordenador durante visita | F4: Semestral (exceto hospital - ver cronograma de visitas) | H4: 1 | J4: =SUM(G4:I10) -> 12
A5: I. Infraestrutura Física | B5: I.2 | C5: Infraestrutura elétrica | D5: Fiação elétrica em bom estado com equipamentos de manutenção de energia elétrica (no-break e/ou gerador) | E5: Observações dos conselheiros e entrevista com o coordenador durante visita | F5: Semestral (exceto hospital - ver cronograma de visitas) | H5: 1
A6: I. Infraestrutura Física | B6: I.3 | D6: Canos, calhas e esgotos sem entupimentos ou vazamentos | E6: Observações dos conselheiros e entrevista com o coordenador durante visita | F6: Semestral (exceto hospital - ver cronograma de visitas) | I6: 2
A7: I. Infraestrutura Física | B7: I.4 | C7: Infraestrutura de comunicação | D7: Disponibilidade de internet, telefones e computadores funcionantes e suficientes para todo o serviço | E7: Observações dos conselheiros e entrevista com o coordenador durante visita | F7: Semestral (exceto hospital - ver cronograma de visitas) | I7: 2
A8: I. Infraestrutura Física | B8: I.5 | C8: Equipamentos | D8: Número suficiente e condições adequadas de utilização dos equipamentos para prestação do serviço | E8: Observações dos conselheiros e entrevista com o coordenador durante visita | F8: Semestral (exceto hospital - ver cronograma de visitas) | I8: 2
A9: I. Infraestrutura Física | B9: I.6 | C9: Materiais, medicamentos e insumos | D9: Materiais e insumos em quantidade, reposição e condições de armazenamento adequadas | E9: Observações dos conselheiros e entrevista com o coordenador durante visita | F9: Semestral (exceto hospital - ver cronograma de visitas) | I9: 2
A10: I. Infraestrutura Física | B10: I.7 | C10: Conforto, limpeza e organização | D10: Ambiente agradável, organizado, sinalizado, com espaço para circulação, boa luminosidade e sem lixo espalhado pelo estabelecimento | E10: Observações dos conselheiros e entrevista com o coordenador durante visita | F10: Semestral (exceto hospital - ver cronograma de visitas) | I10: 2
A11: II. Infraestrutura Humana | B11: II.1 | C11: Utilização de indicadores de gestão | D11: Disponibilidade de dados sobre número de atendimentos, capacidade de serviço, número de altas, número de pacientes cadastrados no serviço, principais queixas dos usuários, entre outros. Evidências sobre decisões da coordenação com base nesses dados. | E11: Apresentação de dados em fala do coordenador e existência de planilhas com os indicadores medidos na Unidade | F11: Semestral (exceto hospital - ver cronograma de visitas) | I11: 2 | J11: =SUM(G11:I14) -> 8
A12: II. Infraestrutura Humana | B12: II.2 | C12: Dimensionamento de equipe | D12: Presença de escalas de trabalho visíveis e obedecidas pelos funcionários da Unidade com cobertura de todos os horários de atendimento | E12: Apresentação, compatibilidade com o trabalho e adequação das escalas e horários de trabalho dos funcionários do estabelecimento de saúde | F12: Semestral (exceto hospital - ver cronograma de visitas) | I12: 2
A13: II. Infraestrutura Humana | B13: II.3 | C13: Execução do cronograma de capacitação da equipe de trabalho | D13: Mecanismos de Educação Permanente dos funcionários planejados e funcionantes | E13: Coordenador da Unidade tem disponível um cronograma de Educação Permanente dos funcionários planejado e realizado | F13: Semestral (exceto hospital - ver cronograma de visitas) | I13: 2
A14: II. Infraestrutura Humana | B14: II.4. | C14: Disponibilidade de agendamento de consultas, exames e procedimentos | D14: Disponibilização de vagas mensais de consultas, exames ou procedimentos compatíveis com a capacidade, a demanda e a pactuação com a SMS | E14: Há um relatório com comparação do número de vagas mensais ofertadas e utilizadas com as consultas, exames ou procedimentos de responsabilidade do estabelecimento | F14: Semestral (exceto hospital - ver cronograma de visitas) | I14: 2
A15: III. Desempenho no Plano Municipal de Saúde | B15: III. 1 | C15: Atendimento aos indicadores do PMS | D15: O estabelecimento de saúde demonstra o cumprimento de todos os indicadores que assumiu para o ano no Plano Municipal de Saúde | E15: Porcentagem de respostas adequadas às questões formuladas para cada indicador do Plano Municipal de Saúde | F15: Semestral | I15: 2 | J15: =SUM(G15:I15) -> 2
A16: IV. Percepção do usuário | B16: IV.1 | C16: Registro de reclamações na Ouvidoria do COMSAUDE | D16: Ausência de registros de reclamações dos usuários sobre o serviço e/ou resolução adequada de eventuais demandas de pequena gravidade existentes | E16: Relatório com número de demandas apresentadas ao COMSAUDE pelos usuários e suas resoluções | F16: Semestral | I16: 2 | J16: =SUM(G16:I17) -> 4
A17: IV. Percepção do usuário | B17: IV.2 | C17: Satisfação dos usuários | D17: Estabelecimento de saúde com alto nível de satisfação do usuário (NPS > 80%) | E17: Resultado de percepção do usuário a partir de entrevistas realizadas durante as visitas do COMSAUDE ao estabelecimento de saúde | F17: Semestral (exceto hospital - ver cronograma de visitas) | I17: 2
A18: Pontuação total da visita realizada em 12/03/2026 | H18: =SUM(H4:H17) -> 2 | I18: =SUM(I4:I17) -> 24 | J18: =SUM(J4:J17) -> 26
A22: Dimensões avaliadas | B22: Número de itens pontuados | C22: Pontuação máxima possível nas dimensões analisadas | D22: Peso da dimensão | E22: UPA D. ROSA | F22: Pontos obtidos por dimensão (exemplo) | G22: % de execução em cada dimensão (exemplo) | H22: Pontuação final (exemplo)
A23: I - Infraestrutura física (prédios, equipamentos e insumos) | B23: 7 | C23: 14 | D23: 0.25 | F23: 12 | G23: =F23/C23 -> 0.85714286 | H23: =G23*D23 -> 0.21428571
A24: II - Infraestrutura humana | B24: 4 | C24: 8 | D24: 0.25 | F24: 8 | G24: =F24/C24 -> 1 | H24: =G24*D24 -> 0.25
A25: III - Desempenho no Plano Municipal de Saúde | B25: 1 | C25: 2 | D25: 0.25 | F25: 2 | G25: =F25/C25 -> 1 | H25: =G25*D25 -> 0.25
A26: IV - Percepção do usuário | B26: 2 | C26: 4 | D26: 0.25 | F26: 4 | G26: =F26/C26 -> 1 | H26: =G26*D26 -> 0.25
A27: Totais | B27: =SUM(B23:B26) -> 14 | C27: =SUM(C23:C26) -> 28 | D27: =SUM(D23:D26) -> 1 | F27: =SUM(F23:F26) -> 26 | G27: - | H27: =SUM(H23:H26) -> 0.96428571

Sheet Banco de Sangue
A1: Dimensões e itens para avaliação global de desempenho dos estabelecimentos municipais de saúde
A3: Dimensões | B3: ID item indicador | C3: Nome do item indicador | D3: Meta esperada no item indicador | E3: Fonte de observação do dado | F3: Periodicidade de observação | G3: Pontuação mínima por item | H3: Pontuação média por item | I3: Pontuação máxima por item | J3: Pontuação por dimensão
A4: I. Infraestrutura Física | B4: I.1 | C4: Infraestrutura civil | D4: Prédio novo ou reformado com paredes e tetos pintados, sem mofo, infiltrações ou goteiras | E4: Observações dos conselheiros e entrevista com o coordenador durante visita | F4: Semestral (exceto hospital - ver cronograma de visitas) | G4: 0 | J4: =SUM(G4:I10) -> 7
A5: I. Infraestrutura Física | B5: I.2 | C5: Infraestrutura elétrica | D5: Fiação elétrica em bom estado com equipamentos de manutenção de energia elétrica (no-break e/ou gerador) | E5: Observações dos conselheiros e entrevista com o coordenador durante visita | F5: Semestral (exceto hospital - ver cronograma de visitas) | G5: 0
A6: I. Infraestrutura Física | B6: I.3 | D6: Canos, calhas e esgotos sem entupimentos ou vazamentos | E6: Observações dos conselheiros e entrevista com o coordenador durante visita | F6: Semestral (exceto hospital - ver cronograma de visitas) | H6: 1
A7: I. Infraestrutura Física | B7: I.4 | C7: Infraestrutura de comunicação | D7: Disponibilidade de internet, telefones e computadores funcionantes e suficientes para todo o serviço | E7: Observações dos conselheiros e entrevista com o coordenador durante visita | F7: Semestral (exceto hospital - ver cronograma de visitas) | I7: 2
A8: I. Infraestrutura Física | B8: I.5 | C8: Equipamentos | D8: Número suficiente e condições adequadas de utilização dos equipamentos para prestação do serviço | E8: Observações dos conselheiros e entrevista com o coordenador durante visita | F8: Semestral (exceto hospital - ver cronograma de visitas) | I8: 2
A9: I. Infraestrutura Física | B9: I.6 | C9: Materiais, medicamentos e insumos | D9: Materiais e insumos em quantidade, reposição e condições de armazenamento adequadas | E9: Observações dos conselheiros e entrevista com o coordenador durante visita | F9: Semestral (exceto hospital - ver cronograma de visitas) | H9: 1
A10: I. Infraestrutura Física | B10: I.7 | C10: Conforto, limpeza e organização | D10: Ambiente agradável, organizado, sinalizado, com espaço para circulação, boa luminosidade e sem lixo espalhado pelo estabelecimento | E10: Observações dos conselheiros e entrevista com o coordenador durante visita | F10: Semestral (exceto hospital - ver cronograma de visitas) | H10: 1
A11: II. Infraestrutura Humana | B11: II.1 | C11: Utilização de indicadores de gestão | D11: Disponibilidade de dados sobre número de atendimentos, capacidade de serviço, número de altas, número de pacientes cadastrados no serviço, principais queixas dos usuários, entre outros. Evidências sobre decisões da coordenação com base nesses dados. | E11: Apresentação de dados em fala do coordenador e existência de planilhas com os indicadores medidos na Unidade | F11: Semestral (exceto hospital - ver cronograma de visitas) | I11: 2 | J11: =SUM(G11:I14) -> 8
A12: II. Infraestrutura Humana | B12: II.2 | C12: Dimensionamento de equipe | D12: Presença de escalas de trabalho visíveis e obedecidas pelos funcionários da Unidade com cobertura de todos os horários de atendimento | E12: Apresentação, compatibilidade com o trabalho e adequação das escalas e horários de trabalho dos funcionários do estabelecimento de saúde | F12: Semestral (exceto hospital - ver cronograma de visitas) | I12: 2
A13: II. Infraestrutura Humana | B13: II.3 | C13: Execução do cronograma de capacitação da equipe de trabalho | D13: Mecanismos de Educação Permanente dos funcionários planejados e funcionantes | E13: Coordenador da Unidade tem disponível um cronograma de Educação Permanente dos funcionários planejado e realizado | F13: Semestral (exceto hospital - ver cronograma de visitas) | I13: 2
A14: II. Infraestrutura Humana | B14: II.4. | C14: Disponibilidade de agendamento de consultas, exames e procedimentos | D14: Disponibilização de vagas mensais de consultas, exames ou procedimentos compatíveis com a capacidade, a demanda e a pactuação com a SMS | E14: Há um relatório com comparação do número de vagas mensais ofertadas e utilizadas com as consultas, exames ou procedimentos de responsabilidade do estabelecimento | F14: Semestral (exceto hospital - ver cronograma de visitas) | I14: 2
A15: III. Desempenho no Plano Municipal de Saúde | B15: III. 1 | C15: Atendimento aos indicadores do PMS | D15: O estabelecimento de saúde demonstra o cumprimento de todos os indicadores que assumiu para o ano no Plano Municipal de Saúde | E15: Porcentagem de respostas adequadas às questões formuladas para cada indicador do Plano Municipal de Saúde | F15: Semestral | H15: 1 | J15: =SUM(G15:I15) -> 1
A16: IV. Percepção do usuário | B16: IV.1 | C16: Registro de reclamações na Ouvidoria do COMSAUDE | D16: Ausência de registros de reclamações dos usuários sobre o serviço e/ou resolução adequada de eventuais demandas de pequena gravidade existentes | E16: Relatório com número de demandas apresentadas ao COMSAUDE pelos usuários e suas resoluções | F16: Semestral | H16: 1 | J16: =SUM(G16:I17) -> 2
A17: IV. Percepção do usuário | B17: IV.2 | C17: Satisfação dos usuários | D17: Estabelecimento de saúde com alto nível de satisfação do usuário (NPS > 80%) | E17: Resultado de percepção do usuário a partir de entrevistas realizadas durante as visitas do COMSAUDE ao estabelecimento de saúde | F17: Semestral (exceto hospital - ver cronograma de visitas) | H17: 1
A18: pontuação total da visita realizada em 10/04/2026 | H18: =SUM(H4:H17) -> 6 | I18: =SUM(I4:I17) -> 12 | J18: =SUM(J4:J17) -> 18
A22: Dimensões avaliadas | B22: Número de itens pontuados | C22: Pontuação máxima possível nas dimensões analisadas | D22: Peso da dimensão | E22: BANCO DE SANGUE | F22: Pontos obtidos por dimensão (exemplo) | G22: % de execução em cada dimensão (exemplo) | H22: Pontuação final (exemplo)
A23: I - Infraestrutura física (prédios, equipamentos e insumos) | B23: 7 | C23: 14 | D23: 0.25 | F23: 7 | G23: =F23/C23 -> 0.5 | H23: =G23*D23 -> 0.125
A24: II - Infraestrutura humana | B24: 4 | C24: 8 | D24: 0.25 | F24: 8 | G24: =F24/C24 -> 1 | H24: =G24*D24 -> 0.25
A25: III - Desempenho no Plano Municipal de Saúde | B25: 1 | C25: 2 | D25: 0.25 | F25: 1 | G25: =F25/C25 -> 0.5 | H25: =G25*D25 -> 0.125
A26: IV - Percepção do usuário | B26: 2 | C26: 4 | D26: 0.25 | F26: 2 | G26: =F26/C26 -> 0.5 | H26: =G26*D26 -> 0.125
A27: Totais | B27: =SUM(B23:B26) -> 14 | C27: =SUM(C23:C26) -> 28 | D27: =SUM(D23:D26) -> 1 | F27: =SUM(F23:F26) -> 18 | G27: - | H27: =SUM(H23:H26) -> 0.625

Sheet UBS Parque Gramado
A1: Dimensões e itens para avaliação global de desempenho dos estabelecimentos municipais de saúde
A3: Dimensões | B3: ID item indicador | C3: Nome do item indicador | D3: Meta esperada no item indicador | E3: Fonte de observação do dado | F3: Periodicidade de observação | G3: Pontuação mínima por item | H3: Pontuação média por item | I3: Pontuação máxima por item | J3: Pontuação por dimensão
A4: I. Infraestrutura Física | B4: I.1 | C4: Infraestrutura civil | D4: Prédio novo ou reformado com paredes e tetos pintados, sem mofo, infiltrações ou goteiras | E4: Observações dos conselheiros e entrevista com o coordenador durante visita | F4: Semestral (exceto hospital - ver cronograma de visitas) | G4: 0 | J4: =SUM(G4:I10) -> 7
A5: I. Infraestrutura Física | B5: I.2 | C5: Infraestrutura elétrica | D5: Fiação elétrica em bom estado com equipamentos de manutenção de energia elétrica (no-break e/ou gerador) | E5: Observações dos conselheiros e entrevista com o coordenador durante visita | F5: Semestral (exceto hospital - ver cronograma de visitas) | H5: 1
A6: I. Infraestrutura Física | B6: I.3 | D6: Canos, calhas e esgotos sem entupimentos ou vazamentos | E6: Observações dos conselheiros e entrevista com o coordenador durante visita | F6: Semestral (exceto hospital - ver cronograma de visitas) | G6: 0
A7: I. Infraestrutura Física | B7: I.4 | C7: Infraestrutura de comunicação | D7: Disponibilidade de internet, telefones e computadores funcionantes e suficientes para todo o serviço | E7: Observações dos conselheiros e entrevista com o coordenador durante visita | F7: Semestral (exceto hospital - ver cronograma de visitas) | I7: 2
A8: I. Infraestrutura Física | B8: I.5 | C8: Equipamentos | D8: Número suficiente e condições adequadas de utilização dos equipamentos para prestação do serviço | E8: Observações dos conselheiros e entrevista com o coordenador durante visita | F8: Semestral (exceto hospital - ver cronograma de visitas) | I8: 2
A9: I. Infraestrutura Física | B9: I.6 | C9: Materiais, medicamentos e insumos | D9: Materiais e insumos em quantidade, reposição e condições de armazenamento adequadas | E9: Observações dos conselheiros e entrevista com o coordenador durante visita | F9: Semestral (exceto hospital - ver cronograma de visitas) | H9: 1
A10: I. Infraestrutura Física | B10: I.7 | C10: Conforto, limpeza e organização | D10: Ambiente agradável, organizado, sinalizado, com espaço para circulação, boa luminosidade e sem lixo espalhado pelo estabelecimento | E10: Observações dos conselheiros e entrevista com o coordenador durante visita | F10: Semestral (exceto hospital - ver cronograma de visitas) | H10: 1
A11: II. Infraestrutura Humana | B11: II.1 | C11: Utilização de indicadores de gestão | D11: Disponibilidade de dados sobre número de atendimentos, capacidade de serviço, número de altas, número de pacientes cadastrados no serviço, principais queixas dos usuários, entre outros. Evidências sobre decisões da coordenação com base nesses dados. | E11: Apresentação de dados em fala do coordenador e existência de planilhas com os indicadores medidos na Unidade | F11: Semestral (exceto hospital - ver cronograma de visitas) | I11: 2 | J11: =SUM(G11:I14) -> 6
A12: II. Infraestrutura Humana | B12: II.2 | C12: Dimensionamento de equipe | D12: Presença de escalas de trabalho visíveis e obedecidas pelos funcionários da Unidade com cobertura de todos os horários de atendimento | E12: Apresentação, compatibilidade com o trabalho e adequação das escalas e horários de trabalho dos funcionários do estabelecimento de saúde | F12: Semestral (exceto hospital - ver cronograma de visitas) | I12: 2
A13: II. Infraestrutura Humana | B13: II.3 | C13: Execução do cronograma de capacitação da equipe de trabalho | D13: Mecanismos de Educação Permanente dos funcionários planejados e funcionantes | E13: Coordenador da Unidade tem disponível um cronograma de Educação Permanente dos funcionários planejado e realizado | F13: Semestral (exceto hospital - ver cronograma de visitas) | H13: 1
A14: II. Infraestrutura Humana | B14: II.4. | C14: Disponibilidade de agendamento de consultas, exames e procedimentos | D14: Disponibilização de vagas mensais de consultas, exames ou procedimentos compatíveis com a capacidade, a demanda e a pactuação com a SMS | E14: Há um relatório com comparação do número de vagas mensais ofertadas e utilizadas com as consultas, exames ou procedimentos de responsabilidade do estabelecimento | F14: Semestral (exceto hospital - ver cronograma de visitas) | H14: 1
A15: III. Desempenho no Plano Municipal de Saúde | B15: III. 1 | C15: Atendimento aos indicadores do PMS | D15: O estabelecimento de saúde demonstra o cumprimento de todos os indicadores que assumiu para o ano no Plano Municipal de Saúde | E15: Porcentagem de respostas adequadas às questões formuladas para cada indicador do Plano Municipal de Saúde | F15: Semestral | H15: 1 | J15: 1
A16: IV. Percepção do usuário | B16: IV.1 | C16: Registro de reclamações na Ouvidoria do COMSAUDE | D16: Ausência de registros de reclamações dos usuários sobre o serviço e/ou resolução adequada de eventuais demandas de pequena gravidade existentes | E16: Relatório com número de demandas apresentadas ao COMSAUDE pelos usuários e suas resoluções | F16: Semestral | I16: 2 | J16: =SUM(G16:I17) -> 4
A17: IV. Percepção do usuário | B17: IV.2 | C17: Satisfação dos usuários | D17: Estabelecimento de saúde com alto nível de satisfação do usuário (NPS > 80%) | E17: Resultado de percepção do usuário a partir de entrevistas realizadas durante as visitas do COMSAUDE ao estabelecimento de saúde | F17: Semestral (exceto hospital - ver cronograma de visitas) | I17: 2
A18: Pontuação total da visita realizada em 14/05/2026 | H18: =SUM(H4:H17) -> 6 | I18: =SUM(I4:I17) -> 12 | J18: =SUM(J4:J17) -> 18
A22: Dimensões avaliadas | B22: Número de itens pontuados | C22: Pontuação máxima possível nas dimensões analisadas | D22: Peso da dimensão | E22: UBS PARQUE GRAMADO | F22: Pontos obtidos por dimensão (exemplo) | G22: % de execução em cada dimensão (exemplo) | H22: Pontuação final (exemplo)
A23: I - Infraestrutura física (prédios, equipamentos e insumos) | B23: 7 | C23: 14 | D23: 0.25 | F23: 7 | G23: =F23/C23 -> 0.5 | H23: =G23*D23 -> 0.125
A24: II - Infraestrutura humana | B24: 4 | C24: 8 | D24: 0.25 | F24: 6 | G24: =F24/C24 -> 0.75 | H24: =G24*D24 -> 0.1875
A25: III - Desempenho no Plano Municipal de Saúde | B25: 1 | C25: 2 | D25: 0.25 | F25: 1 | G25: =F25/C25 -> 0.5 | H25: =G25*D25 -> 0.125
A26: IV - Percepção do usuário | B26: 2 | C26: 4 | D26: 0.25 | F26: 4 | G26: =F26/C26 -> 1 | H26: =G26*D26 -> 0.25
A27: Totais | B27: =SUM(B23:B26) -> 14 | C27: =SUM(C23:C26) -> 28 | D27: =SUM(D23:D26) -> 1 | F27: =SUM(F23:F26) -> 18 | G27: - | H27: =SUM(H23:H26) -> 0.6875

Sheet ESF São José
A1: Dimensões e itens para avaliação global de desempenho dos estabelecimentos municipais de saúde
A3: Dimensões | B3: ID item indicador | C3: Nome do item indicador | D3: Meta esperada no item indicador | E3: Fonte de observação do dado | F3: Periodicidade de observação | G3: Pontuação mínima por item | H3: Pontuação média por item | I3: Pontuação máxima por item | J3: Pontuação por dimensão
A4: I. Infraestrutura Física | B4: I.1 | C4: Infraestrutura civil | D4: Prédio novo ou reformado com paredes e tetos pintados, sem mofo, infiltrações ou goteiras | E4: Observações dos conselheiros e entrevista com o coordenador durante visita | F4: Semestral (exceto hospital - ver cronograma de visitas) | H4: 1 | J4: =SUM(G4:I10) -> 9
A5: I. Infraestrutura Física | B5: I.2 | C5: Infraestrutura elétrica | D5: Fiação elétrica em bom estado com equipamentos de manutenção de energia elétrica (no-break e/ou gerador) | E5: Observações dos conselheiros e entrevista com o coordenador durante visita | F5: Semestral (exceto hospital - ver cronograma de visitas) | H5: 1
A6: I. Infraestrutura Física | B6: I.3 | D6: Canos, calhas e esgotos sem entupimentos ou vazamentos | E6: Observações dos conselheiros e entrevista com o coordenador durante visita | F6: Semestral (exceto hospital - ver cronograma de visitas) | I6: 2
A7: I. Infraestrutura Física | B7: I.4 | C7: Infraestrutura de comunicação | D7: Disponibilidade de internet, telefones e computadores funcionantes e suficientes para todo o serviço | E7: Observações dos conselheiros e entrevista com o coordenador durante visita | F7: Semestral (exceto hospital - ver cronograma de visitas) | H7: 1
A8: I. Infraestrutura Física | B8: I.5 | C8: Equipamentos | D8: Número suficiente e condições adequadas de utilização dos equipamentos para prestação do serviço | E8: Observações dos conselheiros e entrevista com o coordenador durante visita | F8: Semestral (exceto hospital - ver cronograma de visitas) | H8: 1
A9: I. Infraestrutura Física | B9: I.6 | C9: Materiais, medicamentos e insumos | D9: Materiais e insumos em quantidade, reposição e condições de armazenamento adequadas | E9: Observações dos conselheiros e entrevista com o coordenador durante visita | F9: Semestral (exceto hospital - ver cronograma de visitas) | H9: 1
A10: I. Infraestrutura Física | B10: I.7 | C10: Conforto, limpeza e organização | D10: Ambiente agradável, organizado, sinalizado, com espaço para circulação, boa luminosidade e sem lixo espalhado pelo estabelecimento | E10: Observações dos conselheiros e entrevista com o coordenador durante visita | F10: Semestral (exceto hospital - ver cronograma de visitas) | I10: 2
A11: II. Infraestrutura Humana | B11: II.1 | C11: Utilização de indicadores de gestão | D11: Disponibilidade de dados sobre número de atendimentos, capacidade de serviço, número de altas, número de pacientes cadastrados no serviço, principais queixas dos usuários, entre outros. Evidências sobre decisões da coordenação com base nesses dados. | E11: Apresentação de dados em fala do coordenador e existência de planilhas com os indicadores medidos na Unidade | F11: Semestral (exceto hospital - ver cronograma de visitas) | I11: 2 | J11: =SUM(G11:I14) -> 8
A12: II. Infraestrutura Humana | B12: II.2 | C12: Dimensionamento de equipe | D12: Presença de escalas de trabalho visíveis e obedecidas pelos funcionários da Unidade com cobertura de todos os horários de atendimento | E12: Apresentação, compatibilidade com o trabalho e adequação das escalas e horários de trabalho dos funcionários do estabelecimento de saúde | F12: Semestral (exceto hospital - ver cronograma de visitas) | I12: 2
A13: II. Infraestrutura Humana | B13: II.3 | C13: Execução do cronograma de capacitação da equipe de trabalho | D13: Mecanismos de Educação Permanente dos funcionários planejados e funcionantes | E13: Coordenador da Unidade tem disponível um cronograma de Educação Permanente dos funcionários planejado e realizado | F13: Semestral (exceto hospital - ver cronograma de visitas) | I13: 2
A14: II. Infraestrutura Humana | B14: II.4. | C14: Disponibilidade de agendamento de consultas, exames e procedimentos | D14: Disponibilização de vagas mensais de consultas, exames ou procedimentos compatíveis com a capacidade, a demanda e a pactuação com a SMS | E14: Há um relatório com comparação do número de vagas mensais ofertadas e utilizadas com as consultas, exames ou procedimentos de responsabilidade do estabelecimento | F14: Semestral (exceto hospital - ver cronograma de visitas) | I14: 2
A15: III. Desempenho no Plano Municipal de Saúde | B15: III. 1 | C15: Atendimento aos indicadores do PMS | D15: O estabelecimento de saúde demonstra o cumprimento de todos os indicadores que assumiu para o ano no Plano Municipal de Saúde | E15: Porcentagem de respostas adequadas às questões formuladas para cada indicador do Plano Municipal de Saúde | F15: Semestral | I15: 2 | J15: =SUM(G15:I15) -> 2
A16: IV. Percepção do usuário | B16: IV.1 | C16: Registro de reclamações na Ouvidoria do COMSAUDE | D16: Ausência de registros de reclamações dos usuários sobre o serviço e/ou resolução adequada de eventuais demandas de pequena gravidade existentes | E16: Relatório com número de demandas apresentadas ao COMSAUDE pelos usuários e suas resoluções | F16: Semestral | H16: 1 | J16: =SUM(G16:I17) -> 2
A17: IV. Percepção do usuário | B17: IV.2 | C17: Satisfação dos usuários | D17: Estabelecimento de saúde com alto nível de satisfação do usuário (NPS > 80%) | E17: Resultado de percepção do usuário a partir de entrevistas realizadas durante as visitas do COMSAUDE ao estabelecimento de saúde | F17: Semestral (exceto hospital - ver cronograma de visitas) | H17: 1
A18: Pontuação total da visita realizada em 30/04/2026 | H18: =SUM(H4:H17) -> 7 | I18: =SUM(I4:I17) -> 14 | J18: =SUM(J4:J17) -> 21
A22: Dimensões avaliadas | B22: Número de itens pontuados | C22: Pontuação máxima possível nas dimensões analisadas | D22: Peso da dimensão | E22: ESF SÃO VITO | F22: Pontos obtidos por dimensão (exemplo) | G22: % de execução em cada dimensão (exemplo) | H22: Pontuação final (exemplo)
A23: I - Infraestrutura física (prédios, equipamentos e insumos) | B23: 7 | C23: 14 | D23: 0.25 | F23: 9 | G23: =F23/C23 -> 0.64285714 | H23: =G23*D23 -> 0.16071429
A24: II - Infraestrutura humana | B24: 4 | C24: 8 | D24: 0.25 | F24: 8 | G24: =F24/C24 -> 1 | H24: =G24*D24 -> 0.25
A25: III - Desempenho no Plano Municipal de Saúde | B25: 1 | C25: 2 | D25: 0.25 | F25: 2 | G25: =F25/C25 -> 1 | H25: =G25*D25 -> 0.25
A26: IV - Percepção do usuário | B26: 2 | C26: 4 | D26: 0.25 | F26: 2 | G26: =F26/C26 -> 0.5 | H26: =G26*D26 -> 0.125
A27: Totais | B27: =SUM(B23:B26) -> 14 | C27: =SUM(C23:C26) -> 28 | D27: =SUM(D23:D26) -> 1 | F27: =SUM(F23:F26) -> 21 | G27: - | H27: =SUM(H23:H26) -> 0.78571429

Sheet ESF Praia Azul
A1: Dimensões e itens para avaliação global de desempenho dos estabelecimentos municipais de saúde
A3: Dimensões | B3: ID item indicador | C3: Nome do item indicador | D3: Meta esperada no item indicador | E3: Fonte de observação do dado | F3: Periodicidade de observação | G3: Pontuação mínima por item | H3: Pontuação média por item | I3: Pontuação máxima por item | J3: Pontuação por dimensão
A4: I. Infraestrutura Física | B4: I.1 | C4: Infraestrutura civil | D4: Prédio novo ou reformado com paredes e tetos pintados, sem mofo, infiltrações ou goteiras | E4: Observações dos conselheiros e entrevista com o coordenador durante visita | F4: Semestral (exceto hospital - ver cronograma de visitas) | H4: 1 | J4: =SUM(G4:I10) -> 12
A5: I. Infraestrutura Física | B5: I.2 | C5: Infraestrutura elétrica | D5: Fiação elétrica em bom estado com equipamentos de manutenção de energia elétrica (no-break e/ou gerador) | E5: Observações dos conselheiros e entrevista com o coordenador durante visita | F5: Semestral (exceto hospital - ver cronograma de visitas) | H5: 1
A6: I. Infraestrutura Física | B6: I.3 | D6: Canos, calhas e esgotos sem entupimentos ou vazamentos | E6: Observações dos conselheiros e entrevista com o coordenador durante visita | F6: Semestral (exceto hospital - ver cronograma de visitas) | I6: 2
A7: I. Infraestrutura Física | B7: I.4 | C7: Infraestrutura de comunicação | D7: Disponibilidade de internet, telefones e computadores funcionantes e suficientes para todo o serviço | E7: Observações dos conselheiros e entrevista com o coordenador durante visita | F7: Semestral (exceto hospital - ver cronograma de visitas) | I7: 2
A8: I. Infraestrutura Física | B8: I.5 | C8: Equipamentos | D8: Número suficiente e condições adequadas de utilização dos equipamentos para prestação do serviço | E8: Observações dos conselheiros e entrevista com o coordenador durante visita | F8: Semestral (exceto hospital - ver cronograma de visitas) | I8: 2
A9: I. Infraestrutura Física | B9: I.6 | C9: Materiais, medicamentos e insumos | D9: Materiais e insumos em quantidade, reposição e condições de armazenamento adequadas | E9: Observações dos conselheiros e entrevista com o coordenador durante visita | F9: Semestral (exceto hospital - ver cronograma de visitas) | I9: 2
A10: I. Infraestrutura Física | B10: I.7 | C10: Conforto, limpeza e organização | D10: Ambiente agradável, organizado, sinalizado, com espaço para circulação, boa luminosidade e sem lixo espalhado pelo estabelecimento | E10: Observações dos conselheiros e entrevista com o coordenador durante visita | F10: Semestral (exceto hospital - ver cronograma de visitas) | I10: 2
A11: II. Infraestrutura Humana | B11: II.1 | C11: Utilização de indicadores de gestão | D11: Disponibilidade de dados sobre número de atendimentos, capacidade de serviço, número de altas, número de pacientes cadastrados no serviço, principais queixas dos usuários, entre outros. Evidências sobre decisões da coordenação com base nesses dados. | E11: Apresentação de dados em fala do coordenador e existência de planilhas com os indicadores medidos na Unidade | F11: Semestral (exceto hospital - ver cronograma de visitas) | I11: 2 | J11: =SUM(G11:I14) -> 8
A12: II. Infraestrutura Humana | B12: II.2 | C12: Dimensionamento de equipe | D12: Presença de escalas de trabalho visíveis e obedecidas pelos funcionários da Unidade com cobertura de todos os horários de atendimento | E12: Apresentação, compatibilidade com o trabalho e adequação das escalas e horários de trabalho dos funcionários do estabelecimento de saúde | F12: Semestral (exceto hospital - ver cronograma de visitas) | I12: 2
A13: II. Infraestrutura Humana | B13: II.3 | C13: Execução do cronograma de capacitação da equipe de trabalho | D13: Mecanismos de Educação Permanente dos funcionários planejados e funcionantes | E13: Coordenador da Unidade tem disponível um cronograma de Educação Permanente dos funcionários planejado e realizado | F13: Semestral (exceto hospital - ver cronograma de visitas) | I13: 2
A14: II. Infraestrutura Humana | B14: II.4. | C14: Disponibilidade de agendamento de consultas, exames e procedimentos | D14: Disponibilização de vagas mensais de consultas, exames ou procedimentos compatíveis com a capacidade, a demanda e a pactuação com a SMS | E14: Há um relatório com comparação do número de vagas mensais ofertadas e utilizadas com as consultas, exames ou procedimentos de responsabilidade do estabelecimento | F14: Semestral (exceto hospital - ver cronograma de visitas) | I14: 2
A15: III. Desempenho no Plano Municipal de Saúde | B15: III. 1 | C15: Atendimento aos indicadores do PMS | D15: O estabelecimento de saúde demonstra o cumprimento de todos os indicadores que assumiu para o ano no Plano Municipal de Saúde | E15: Porcentagem de respostas adequadas às questões formuladas para cada indicador do Plano Municipal de Saúde | F15: Semestral | I15: 2 | J15: =SUM(G15:I15) -> 2
A16: IV. Percepção do usuário | B16: IV.1 | C16: Registro de reclamações na Ouvidoria do COMSAUDE | D16: Ausência de registros de reclamações dos usuários sobre o serviço e/ou resolução adequada de eventuais demandas de pequena gravidade existentes | E16: Relatório com número de demandas apresentadas ao COMSAUDE pelos usuários e suas resoluções | F16: Semestral | I16: 2 | J16: =SUM(G16:I17) -> 3
A17: IV. Percepção do usuário | B17: IV.2 | C17: Satisfação dos usuários | D17: Estabelecimento de saúde com alto nível de satisfação do usuário (NPS > 80%) | E17: Resultado de percepção do usuário a partir de entrevistas realizadas durante as visitas do COMSAUDE ao estabelecimento de saúde | F17: Semestral (exceto hospital - ver cronograma de visitas) | H17: 1
A18: Pontuação total da visita realizada em 17/06/2026 | H18: =SUM(H4:H17) -> 3 | I18: =SUM(I4:I17) -> 22 | J18: =SUM(J4:J17) -> 25
A22: Dimensões avaliadas | B22: Número de itens pontuados | C22: Pontuação máxima possível nas dimensões analisadas | D22: Peso da dimensão | E22: ESF PRAIA AZUL | F22: Pontos obtidos por dimensão (exemplo) | G22: % de execução em cada dimensão (exemplo) | H22: Pontuação final (exemplo)
A23: I - Infraestrutura física (prédios, equipamentos e insumos) | B23: 7 | C23: 14 | D23: 0.25 | F23: 12 | G23: =F23/C23 -> 0.85714286 | H23: =G23*D23 -> 0.21428571
A24: II - Infraestrutura humana | B24: 4 | C24: 8 | D24: 0.25 | F24: 8 | G24: =F24/C24 -> 1 | H24: =G24*D24 -> 0.25
A25: III - Desempenho no Plano Municipal de Saúde | B25: 1 | C25: 2 | D25: 0.25 | F25: 2 | G25: =F25/C25 -> 1 | H25: =G25*D25 -> 0.25
A26: IV - Percepção do usuário | B26: 2 | C26: 4 | D26: 0.25 | F26: 3 | G26: =F26/C26 -> 0.75 | H26: =G26*D26 -> 0.1875
A27: Totais | B27: =SUM(B23:B26) -> 14 | C27: =SUM(C23:C26) -> 28 | D27: =SUM(D23:D26) -> 1 | F27: =SUM(F23:F26) -> 25 | G27: - | H27: =SUM(H23:H26) -> 0.90178571

Sheet ESF Jardim Brasil
A1: Dimensões e itens para avaliação global de desempenho dos estabelecimentos municipais de saúde
A3: Dimensões | B3: ID item indicador | C3: Nome do item indicador | D3: Meta esperada no item indicador | E3: Fonte de observação do dado | F3: Periodicidade de observação | G3: Pontuação mínima por item | H3: Pontuação média por item | I3: Pontuação máxima por item | J3: Pontuação por dimensão
A4: I. Infraestrutura Física | B4: I.1 | C4: Infraestrutura civil | D4: Prédio novo ou reformado com paredes e tetos pintados, sem mofo, infiltrações ou goteiras | E4: Observações dos conselheiros e entrevista com o coordenador durante visita | F4: Semestral (exceto hospital - ver cronograma de visitas) | I4: 2 | J4: =SUM(G4:I10) -> 14
A5: I. Infraestrutura Física | B5: I.2 | C5: Infraestrutura elétrica | D5: Fiação elétrica em bom estado com equipamentos de manutenção de energia elétrica (no-break e/ou gerador) | E5: Observações dos conselheiros e entrevista com o coordenador durante visita | F5: Semestral (exceto hospital - ver cronograma de visitas) | I5: 2
A6: I. Infraestrutura Física | B6: I.3 | D6: Canos, calhas e esgotos sem entupimentos ou vazamentos | E6: Observações dos conselheiros e entrevista com o coordenador durante visita | F6: Semestral (exceto hospital - ver cronograma de visitas) | I6: 2
A7: I. Infraestrutura Física | B7: I.4 | C7: Infraestrutura de comunicação | D7: Disponibilidade de internet, telefones e computadores funcionantes e suficientes para todo o serviço | E7: Observações dos conselheiros e entrevista com o coordenador durante visita | F7: Semestral (exceto hospital - ver cronograma de visitas) | I7: 2
A8: I. Infraestrutura Física | B8: I.5 | C8: Equipamentos | D8: Número suficiente e condições adequadas de utilização dos equipamentos para prestação do serviço | E8: Observações dos conselheiros e entrevista com o coordenador durante visita | F8: Semestral (exceto hospital - ver cronograma de visitas) | I8: 2
A9: I. Infraestrutura Física | B9: I.6 | C9: Materiais, medicamentos e insumos | D9: Materiais e insumos em quantidade, reposição e condições de armazenamento adequadas | E9: Observações dos conselheiros e entrevista com o coordenador durante visita | F9: Semestral (exceto hospital - ver cronograma de visitas) | I9: 2
A10: I. Infraestrutura Física | B10: I.7 | C10: Conforto, limpeza e organização | D10: Ambiente agradável, organizado, sinalizado, com espaço para circulação, boa luminosidade e sem lixo espalhado pelo estabelecimento | E10: Observações dos conselheiros e entrevista com o coordenador durante visita | F10: Semestral (exceto hospital - ver cronograma de visitas) | I10: 2
A11: II. Infraestrutura Humana | B11: II.1 | C11: Utilização de indicadores de gestão | D11: Disponibilidade de dados sobre número de atendimentos, capacidade de serviço, número de altas, número de pacientes cadastrados no serviço, principais queixas dos usuários, entre outros. Evidências sobre decisões da coordenação com base nesses dados. | E11: Apresentação de dados em fala do coordenador e existência de planilhas com os indicadores medidos na Unidade | F11: Semestral (exceto hospital - ver cronograma de visitas) | I11: 2 | J11: =SUM(G11:I14) -> 8
A12: II. Infraestrutura Humana | B12: II.2 | C12: Dimensionamento de equipe | D12: Presença de escalas de trabalho visíveis e obedecidas pelos funcionários da Unidade com cobertura de todos os horários de atendimento | E12: Apresentação, compatibilidade com o trabalho e adequação das escalas e horários de trabalho dos funcionários do estabelecimento de saúde | F12: Semestral (exceto hospital - ver cronograma de visitas) | I12: 2
A13: II. Infraestrutura Humana | B13: II.3 | C13: Execução do cronograma de capacitação da equipe de trabalho | D13: Mecanismos de Educação Permanente dos funcionários planejados e funcionantes | E13: Coordenador da Unidade tem disponível um cronograma de Educação Permanente dos funcionários planejado e realizado | F13: Semestral (exceto hospital - ver cronograma de visitas) | I13: 2
A14: II. Infraestrutura Humana | B14: II.4. | C14: Disponibilidade de agendamento de consultas, exames e procedimentos | D14: Disponibilização de vagas mensais de consultas, exames ou procedimentos compatíveis com a capacidade, a demanda e a pactuação com a SMS | E14: Há um relatório com comparação do número de vagas mensais ofertadas e utilizadas com as consultas, exames ou procedimentos de responsabilidade do estabelecimento | F14: Semestral (exceto hospital - ver cronograma de visitas) | I14: 2
A15: III. Desempenho no Plano Municipal de Saúde | B15: III. 1 | C15: Atendimento aos indicadores do PMS | D15: O estabelecimento de saúde demonstra o cumprimento de todos os indicadores que assumiu para o ano no Plano Municipal de Saúde | E15: Porcentagem de respostas adequadas às questões formuladas para cada indicador do Plano Municipal de Saúde | F15: Semestral | I15: 2 | J15: =SUM(G15:I15) -> 2
A16: IV. Percepção do usuário | B16: IV.1 | C16: Registro de reclamações na Ouvidoria do COMSAUDE | D16: Ausência de registros de reclamações dos usuários sobre o serviço e/ou resolução adequada de eventuais demandas de pequena gravidade existentes | E16: Relatório com número de demandas apresentadas ao COMSAUDE pelos usuários e suas resoluções | F16: Semestral | I16: 2 | J16: =SUM(G16:I17) -> 4
A17: IV. Percepção do usuário | B17: IV.2 | C17: Satisfação dos usuários | D17: Estabelecimento de saúde com alto nível de satisfação do usuário (NPS > 80%) | E17: Resultado de percepção do usuário a partir de entrevistas realizadas durante as visitas do COMSAUDE ao estabelecimento de saúde | F17: Semestral (exceto hospital - ver cronograma de visitas) | I17: 2
A18: Pontuação total da visita realizada em 20/05/2026 | H18: =SUM(H4:H17) -> 0 | I18: =SUM(I4:I17) -> 28 | J18: =SUM(J4:J17) -> 28
A22: Dimensões avaliadas | B22: Número de itens pontuados | C22: Pontuação máxima possível nas dimensões analisadas | D22: Peso da dimensão | E22: ESF JARDIM BRASIL | F22: Pontos obtidos por dimensão (exemplo) | G22: % de execução em cada dimensão (exemplo) | H22: Pontuação final (exemplo)
